Workbook

Sheet 읽어주세요
A1: 쏠 아스트로 하우스 — 해석 DB v1.2 (초안)
A2: 기준일 2026-10-07 · 상태: 상담사 검수 전 초안 · 전체 1366행
A4: 검수 방법
A5: • 각 DB 시트 오른쪽 노란 칸 3개만 입력합니다: 검수상태(목록에서 선택) · 수정 문장(고칠 때만) · 상담사 메모.
A6: • 검수상태 값: 미검수 / 승인 / 수정필요 / 삭제. 요약 시트가 DB별 진행률을 자동으로 셉니다.
A7: • review_note(작성 메모) 열은 초안 작성 시 확인받고 싶었던 점입니다. 먼저 읽어 주세요.
A8: • 문장 규칙: ** 금지, 문장 칸에 숫자 금지(토큰 사용), 입니다체·해요체 교대, 이론명·진단명 금지, 단정·공포 표현 금지.
A9: • 예시: A5 수달 행 → 검수상태 "승인", 수정 문장 비움 / 고칠 때는 "수정필요" + 수정 문장 칸에 고친 문장 전체.
A11: 토큰 사전 (서버가 실제 값으로 바꿈)
A12: 토큰 | B12: 뜻 | C12: 쓰는 DB
A13: {닉네임} | B13: 사용자 닉네임(님은 문장에 붙여 씀) | C13: A15 등
A14: {{근거}} | B14: 바람을 돕거나 막는 행성 근거 구절, "-는"으로 끝남 (예: 목성이 집·뿌리의 자리를 지나는) | C14: A13
A15: {{열리는해}} | B15: 바람이 열리는 첫 순풍 연도 (예: 2028년) | C15: A13
A16: {{가까운해}} | B16: 5년 안에 순풍이 없을 때 지원도가 가장 높은 연도 | C16: A13
A17: {{기질문장}} | B17: A17b temperament_line을 그대로 넣음(없으면 빈칸) | C17: A17a
A18: {{태양별자리}} / {{달별자리}} | B18: 사용자 태양·달 별자리 이름 | C18: A17b
A19: {{날짜}} | B19: 이벤트 날짜 (예: 4월 26일) | C19: A18
A20: {{하우스영역}} | B20: A16 하우스 nickname (예: 사람들·공동체의 자리) | C20: A18
A21: {{별자리}} | B21: 이벤트 별자리 | C21: A18
A22: {{행성}} / {{행성:이/가}} | B22: 행성 이름, 조사는 josa 함수가 받침에 맞춰 처리 | C22: A18

Sheet 요약
A1: DB | B1: 이름 | C1: 화면에서 쓰는 곳 | D1: 행 수 | E1: 승인 | F1: 수정필요 | G1: 삭제 | H1: 미검수 | I1: 진행률
A2: A1 | B2: 별자리 기본 정보 | C2: 태양·달·상승궁 표, 휠 별자리 칸 탭 | D2: =COUNTA('A1 별자리 기본 정보'!A2:A13) -> 12 | E2: =COUNTIF('A1 별자리 기본 정보'!M2:M13,"승인") -> 0 | F2: =COUNTIF('A1 별자리 기본 정보'!M2:M13,"수정필요") -> 0 | G2: =COUNTIF('A1 별자리 기본 정보'!M2:M13,"삭제") -> 0 | H2: =COUNTIF('A1 별자리 기본 정보'!M2:M13,"미검수") -> 12 | I2: =IFERROR((E2+G2)/D2,0) -> 0
A3: A2 | B3: 태양 × 별자리 | C3: 태양·달·상승궁 표(태양 행) | D3: =COUNTA('A2 태양 × 별자리'!A2:A13) -> 12 | E3: =COUNTIF('A2 태양 × 별자리'!G2:G13,"승인") -> 0 | F3: =COUNTIF('A2 태양 × 별자리'!G2:G13,"수정필요") -> 0 | G3: =COUNTIF('A2 태양 × 별자리'!G2:G13,"삭제") -> 0 | H3: =COUNTIF('A2 태양 × 별자리'!G2:G13,"미검수") -> 12 | I3: =IFERROR((E3+G3)/D3,0) -> 0
A4: A3 | B4: 달 × 별자리 | C4: 태양·달·상승궁 표(달 행) | D4: =COUNTA('A3 달 × 별자리'!A2:A13) -> 12 | E4: =COUNTIF('A3 달 × 별자리'!G2:G13,"승인") -> 0 | F4: =COUNTIF('A3 달 × 별자리'!G2:G13,"수정필요") -> 0 | G4: =COUNTIF('A3 달 × 별자리'!G2:G13,"삭제") -> 0 | H4: =COUNTIF('A3 달 × 별자리'!G2:G13,"미검수") -> 12 | I4: =IFERROR((E4+G4)/D4,0) -> 0
A5: A4 | B5: 상승궁 × 별자리 | C5: 태양·달·상승궁 표(상승궁 행, 정확도 A·B등급만) | D5: =COUNTA('A4 상승궁 × 별자리'!A2:A13) -> 12 | E5: =COUNTIF('A4 상승궁 × 별자리'!F2:F13,"승인") -> 0 | F5: =COUNTIF('A4 상승궁 × 별자리'!F2:F13,"수정필요") -> 0 | G5: =COUNTIF('A4 상승궁 × 별자리'!F2:F13,"삭제") -> 0 | H5: =COUNTIF('A4 상승궁 × 별자리'!F2:F13,"미검수") -> 12 | I5: =IFERROR((E5+G5)/D5,0) -> 0
A6: A5 | B6: 캐릭터 20종 (점성술판) | C6: 2번 섹션 — 당분간 show_character=false: 동물 이름·intro·share_line은 화면에 쓰지 않고 type_line + why_text만 사용 | D6: =COUNTA('A5 캐릭터 20종 (점성술판)'!A2:A21) -> 20 | E6: =COUNTIF('A5 캐릭터 20종 (점성술판)'!P2:P21,"승인") -> 0 | F6: =COUNTIF('A5 캐릭터 20종 (점성술판)'!P2:P21,"수정필요") -> 0 | G6: =COUNTIF('A5 캐릭터 20종 (점성술판)'!P2:P21,"삭제") -> 0 | H6: =COUNTIF('A5 캐릭터 20종 (점성술판)'!P2:P21,"미검수") -> 20 | I6: =IFERROR((E6+G6)/D6,0) -> 0
A7: A6 | B7: 역량 5 · 방식 4 설명 | C7: 2번 섹션 캐릭터 설명 | D7: =COUNTA('A6 역량 5 · 방식 4 설명'!A2:A10) -> 9 | E7: =COUNTIF('A6 역량 5 · 방식 4 설명'!I2:I10,"승인") -> 0 | F7: =COUNTIF('A6 역량 5 · 방식 4 설명'!I2:I10,"수정필요") -> 0 | G7: =COUNTIF('A6 역량 5 · 방식 4 설명'!I2:I10,"삭제") -> 0 | H7: =COUNTIF('A6 역량 5 · 방식 4 설명'!I2:I10,"미검수") -> 9 | I7: =IFERROR((E7+G7)/D7,0) -> 0
A8: A7 | B8: 원소 강할 때·부족할 때 | C8: 4원소 막대 아래 문장 | D8: =COUNTA('A7 원소 강할 때·부족할 때'!A2:A9) -> 8 | E8: =COUNTIF('A7 원소 강할 때·부족할 때'!G2:G9,"승인") -> 0 | F8: =COUNTIF('A7 원소 강할 때·부족할 때'!G2:G9,"수정필요") -> 0 | G8: =COUNTIF('A7 원소 강할 때·부족할 때'!G2:G9,"삭제") -> 0 | H8: =COUNTIF('A7 원소 강할 때·부족할 때'!G2:G9,"미검수") -> 8 | I8: =IFERROR((E8+G8)/D8,0) -> 0
A9: A8 | B9: 트랜짓 이벤트 문장 | C9: 2026 회고(무료) 분기 표·접힌 근거, 2027·5년 파트 핵심 문장 | D9: =COUNTA('A8 트랜짓 이벤트 문장'!A2:A107) -> 106 | E9: =COUNTIF('A8 트랜짓 이벤트 문장'!M2:M107,"승인") -> 0 | F9: =COUNTIF('A8 트랜짓 이벤트 문장'!M2:M107,"수정필요") -> 0 | G9: =COUNTIF('A8 트랜짓 이벤트 문장'!M2:M107,"삭제") -> 0 | H9: =COUNTIF('A8 트랜짓 이벤트 문장'!M2:M107,"미검수") -> 106 | I9: =IFERROR((E9+G9)/D9,0) -> 0
A10: A9 | B10: 목성·토성 하우스 통과 | C10: 2027 한 해 키워드·분기 표, 5년 연도별 테마 | D10: =COUNTA('A9 목성·토성 하우스 통과'!A2:A25) -> 24 | E10: =COUNTIF('A9 목성·토성 하우스 통과'!L2:L25,"승인") -> 0 | F10: =COUNTIF('A9 목성·토성 하우스 통과'!L2:L25,"수정필요") -> 0 | G10: =COUNTIF('A9 목성·토성 하우스 통과'!L2:L25,"삭제") -> 0 | H10: =COUNTIF('A9 목성·토성 하우스 통과'!L2:L25,"미검수") -> 24 | I10: =IFERROR((E10+G10)/D10,0) -> 0
A11: A10 | B11: 연말·단기 역행 | C11: 연말 월별 표('무엇을 조심할까'), 접힌 근거('왜 그럴까'), 2027 1분기(화성 역행) | D11: =COUNTA('A10 연말·단기 역행'!A2:A37) -> 36 | E11: =COUNTIF('A10 연말·단기 역행'!J2:J37,"승인") -> 0 | F11: =COUNTIF('A10 연말·단기 역행'!J2:J37,"수정필요") -> 0 | G11: =COUNTIF('A10 연말·단기 역행'!J2:J37,"삭제") -> 0 | H11: =COUNTIF('A10 연말·단기 역행'!J2:J37,"미검수") -> 36 | I11: =IFERROR((E11+G11)/D11,0) -> 0
A12: A11 | B12: 하늘의 공통 흐름 2026말~2031 | C12: 5년 타임라인 배경, 공통 문구 | D12: =COUNTA('A11 하늘의 공통 흐름 2026말~2031'!A2:A11) -> 10 | E12: =COUNTIF('A11 하늘의 공통 흐름 2026말~2031'!G2:G11,"승인") -> 0 | F12: =COUNTIF('A11 하늘의 공통 흐름 2026말~2031'!G2:G11,"수정필요") -> 0 | G12: =COUNTIF('A11 하늘의 공통 흐름 2026말~2031'!G2:G11,"삭제") -> 0 | H12: =COUNTIF('A11 하늘의 공통 흐름 2026말~2031'!G2:G11,"미검수") -> 10 | I12: =IFERROR((E12+G12)/D12,0) -> 0
A13: A12 | B13: Q2 공감 도입문 (2026 한 단어) | C13: 2026 회고 섹션 두 번째 문단(첫 문단은 결론) · closing은 같은 섹션 마지막 문단 · care_note는 부드러운 톤(soft=Y)일 때 결과 하단 | D13: =COUNTA('A12 Q2 공감 도입문 (2026 한 단어)'!A2:A11) -> 10 | E13: =COUNTIF('A12 Q2 공감 도입문 (2026 한 단어)'!I2:I11,"승인") -> 0 | F13: =COUNTIF('A12 Q2 공감 도입문 (2026 한 단어)'!I2:I11,"수정필요") -> 0 | G13: =COUNTIF('A12 Q2 공감 도입문 (2026 한 단어)'!I2:I11,"삭제") -> 0 | H13: =COUNTIF('A12 Q2 공감 도입문 (2026 한 단어)'!I2:I11,"미검수") -> 10 | I13: =IFERROR((E13+G13)/D13,0) -> 0
A14: A12b | B14: 2026 회고 표현 변형 | C14: 3번 섹션(2026 회고) 첫 문단·마무리 — A12의 1번 표현과 합쳐 칸마다 5개 중 하나를 고름(같은 출생정보면 같은 표현: 출생정보 해시로 고정) | D14: =COUNTA('A12b 2026 회고 표현 변형'!A2:A121) -> 120 | E14: =COUNTIF('A12b 2026 회고 표현 변형'!G2:G121,"승인") -> 0 | F14: =COUNTIF('A12b 2026 회고 표현 변형'!G2:G121,"수정필요") -> 0 | G14: =COUNTIF('A12b 2026 회고 표현 변형'!G2:G121,"삭제") -> 0 | H14: =COUNTIF('A12b 2026 회고 표현 변형'!G2:G121,"미검수") -> 120 | I14: =IFERROR((E14+G14)/D14,0) -> 0
A15: A13 | B15: Q3 바람 × 판정 (이루어짐) | C15: 2027 마음가짐 판정 문단, 5년 표 '바람' 칸, 열리는 해 | D15: =COUNTA('A13 Q3 바람 × 판정 (이루어짐)'!A2:A45) -> 44 | E15: =COUNTIF('A13 Q3 바람 × 판정 (이루어짐)'!H2:H45,"승인") -> 0 | F15: =COUNTIF('A13 Q3 바람 × 판정 (이루어짐)'!H2:H45,"수정필요") -> 0 | G15: =COUNTIF('A13 Q3 바람 × 판정 (이루어짐)'!H2:H45,"삭제") -> 0 | H15: =COUNTIF('A13 Q3 바람 × 판정 (이루어짐)'!H2:H45,"미검수") -> 44 | I15: =IFERROR((E15+G15)/D15,0) -> 0
A16: A13b | B16: 바람 판정 표현 변형 | C16: 5번(2027)·6번(5년) 섹션 판정 문단 — A13의 1번 표현과 합쳐 칸마다 5개 중 하나를 고름(같은 출생정보면 같은 표현: 출생정보 해시로 고정) | D16: =COUNTA('A13b 바람 판정 표현 변형'!A2:A221) -> 220 | E16: =COUNTIF('A13b 바람 판정 표현 변형'!H2:H221,"승인") -> 0 | F16: =COUNTIF('A13b 바람 판정 표현 변형'!H2:H221,"수정필요") -> 0 | G16: =COUNTIF('A13b 바람 판정 표현 변형'!H2:H221,"삭제") -> 0 | H16: =COUNTIF('A13b 바람 판정 표현 변형'!H2:H221,"미검수") -> 220 | I16: =IFERROR((E16+G16)/D16,0) -> 0
A17: A14 | B17: 웰니스 실천 (역량 × 고민 영역) | C17: 7번 섹션 '작은 실천 3가지', 연말 파트 '• 작은 실천' — 실천 통합본 v1.0에서 선택 | D17: =COUNTA('A14 웰니스 실천 (역량 × 고민 영역)'!A2:A31) -> 30 | E17: =COUNTIF('A14 웰니스 실천 (역량 × 고민 영역)'!X2:X31,"승인") -> 0 | F17: =COUNTIF('A14 웰니스 실천 (역량 × 고민 영역)'!X2:X31,"수정필요") -> 0 | G17: =COUNTIF('A14 웰니스 실천 (역량 × 고민 영역)'!X2:X31,"삭제") -> 0 | H17: =COUNTIF('A14 웰니스 실천 (역량 × 고민 영역)'!X2:X31,"미검수") -> 30 | I17: =IFERROR((E17+G17)/D17,0) -> 0
A18: A15 | B18: 고정 문구 | C18: 고지·정확도 배지·휠 안내·캐릭터 확인 화면·결제 상자·리포트 끝·상담 카드·빈 영역·로딩·개인정보 안내 | D18: =COUNTA('A15 고정 문구'!A2:A17) -> 16 | E18: =COUNTIF('A15 고정 문구'!E2:E17,"승인") -> 0 | F18: =COUNTIF('A15 고정 문구'!E2:E17,"수정필요") -> 0 | G18: =COUNTIF('A15 고정 문구'!E2:E17,"삭제") -> 0 | H18: =COUNTIF('A15 고정 문구'!E2:E17,"미검수") -> 16 | I18: =IFERROR((E18+G18)/D18,0) -> 0
A19: A16 | B19: 행성·각도·하우스 뜻 (용어 사전) | C19: 시기별 표 접힌 근거의 ‘뜻 한 줄’ 조립 · 출생차트 휠 탭 시트 | D19: =COUNTA('A16 행성·각도·하우스 뜻 (용어 사전)'!A2:A36) -> 35 | E19: =COUNTIF('A16 행성·각도·하우스 뜻 (용어 사전)'!H2:H36,"승인") -> 0 | F19: =COUNTIF('A16 행성·각도·하우스 뜻 (용어 사전)'!H2:H36,"수정필요") -> 0 | G19: =COUNTIF('A16 행성·각도·하우스 뜻 (용어 사전)'!H2:H36,"삭제") -> 0 | H19: =COUNTIF('A16 행성·각도·하우스 뜻 (용어 사전)'!H2:H36,"미검수") -> 35 | I19: =IFERROR((E19+G19)/D19,0) -> 0
A20: A17a | B20: 성찰 질문 은행 (역량 × 2027 바람) | C20: 7번 섹션 질문 3개 + 왜 이 질문인지 | D20: =COUNTA('A17a 성찰 질문 은행 (역량 × 2027 바람)'!A2:A56) -> 55 | E20: =COUNTIF('A17a 성찰 질문 은행 (역량 × 2027 바람)'!J2:J56,"승인") -> 0 | F20: =COUNTIF('A17a 성찰 질문 은행 (역량 × 2027 바람)'!J2:J56,"수정필요") -> 0 | G20: =COUNTIF('A17a 성찰 질문 은행 (역량 × 2027 바람)'!J2:J56,"삭제") -> 0 | H20: =COUNTIF('A17a 성찰 질문 은행 (역량 × 2027 바람)'!J2:J56,"미검수") -> 55 | I20: =IFERROR((E20+G20)/D20,0) -> 0
A21: A17b | B21: 기질 문장 (태양 원소 × 달 원소) | C21: 캐릭터 섹션 태양·달 대비 문단, 7번 섹션 ‘왜 이 질문인지’의 기질 문장 | D21: =COUNTA('A17b 기질 문장 (태양 원소 × 달 원소)'!A2:A17) -> 16 | E21: =COUNTIF('A17b 기질 문장 (태양 원소 × 달 원소)'!G2:G17,"승인") -> 0 | F21: =COUNTIF('A17b 기질 문장 (태양 원소 × 달 원소)'!G2:G17,"수정필요") -> 0 | G21: =COUNTIF('A17b 기질 문장 (태양 원소 × 달 원소)'!G2:G17,"삭제") -> 0 | H21: =COUNTIF('A17b 기질 문장 (태양 원소 × 달 원소)'!G2:G17,"미검수") -> 16 | I21: =IFERROR((E21+G21)/D21,0) -> 0
A22: A18 | B22: 전환점 문장 (올해의 전환점) | C22: 2026 회고 '• 올해의 전환점' 본문 문단 | D22: =COUNTA('A18 전환점 문장 (올해의 전환점)'!A2:A21) -> 20 | E22: =COUNTIF('A18 전환점 문장 (올해의 전환점)'!F2:F21,"승인") -> 0 | F22: =COUNTIF('A18 전환점 문장 (올해의 전환점)'!F2:F21,"수정필요") -> 0 | G22: =COUNTIF('A18 전환점 문장 (올해의 전환점)'!F2:F21,"삭제") -> 0 | H22: =COUNTIF('A18 전환점 문장 (올해의 전환점)'!F2:F21,"미검수") -> 20 | I22: =IFERROR((E22+G22)/D22,0) -> 0
A23: B1a | B23: 행성 × 별자리 (수성·금성·화성·목성·토성) | C23: 출생차트 휠 행성 탭 시트(태양·달·상승궁 외 행성; 무료는 첫 문장만, 나머지 블러) | D23: =COUNTA('B1a 행성 × 별자리 (수성·금성·화성·목성·토성)'!A2:A61) -> 60 | E23: =COUNTIF('B1a 행성 × 별자리 (수성·금성·화성·목성·토성)'!G2:G61,"승인") -> 0 | F23: =COUNTIF('B1a 행성 × 별자리 (수성·금성·화성·목성·토성)'!G2:G61,"수정필요") -> 0 | G23: =COUNTIF('B1a 행성 × 별자리 (수성·금성·화성·목성·토성)'!G2:G61,"삭제") -> 0 | H23: =COUNTIF('B1a 행성 × 별자리 (수성·금성·화성·목성·토성)'!G2:G61,"미검수") -> 60 | I23: =IFERROR((E23+G23)/D23,0) -> 0
A24: B1b | B24: 세대 행성 × 별자리 (천왕성·해왕성·명왕성) | C24: 출생차트 휠 행성 탭 시트 | D24: =COUNTA('B1b 세대 행성 × 별자리 (천왕성·해왕성·명왕성)'!A2:A37) -> 36 | E24: =COUNTIF('B1b 세대 행성 × 별자리 (천왕성·해왕성·명왕성)'!H2:H37,"승인") -> 0 | F24: =COUNTIF('B1b 세대 행성 × 별자리 (천왕성·해왕성·명왕성)'!H2:H37,"수정필요") -> 0 | G24: =COUNTIF('B1b 세대 행성 × 별자리 (천왕성·해왕성·명왕성)'!H2:H37,"삭제") -> 0 | H24: =COUNTIF('B1b 세대 행성 × 별자리 (천왕성·해왕성·명왕성)'!H2:H37,"미검수") -> 36 | I24: =IFERROR((E24+G24)/D24,0) -> 0
A25: B2a | B25: 행성 × 하우스 (태양·달·수성·금성·화성) | C25: 출생차트 휠 행성 탭 시트·태양/달 표의 하우스 문장 (정확도 A·B등급만) | D25: =COUNTA('B2a 행성 × 하우스 (태양·달·수성·금성·화성)'!A2:A61) -> 60 | E25: =COUNTIF('B2a 행성 × 하우스 (태양·달·수성·금성·화성)'!H2:H61,"승인") -> 0 | F25: =COUNTIF('B2a 행성 × 하우스 (태양·달·수성·금성·화성)'!H2:H61,"수정필요") -> 0 | G25: =COUNTIF('B2a 행성 × 하우스 (태양·달·수성·금성·화성)'!H2:H61,"삭제") -> 0 | H25: =COUNTIF('B2a 행성 × 하우스 (태양·달·수성·금성·화성)'!H2:H61,"미검수") -> 60 | I25: =IFERROR((E25+G25)/D25,0) -> 0
A26: B2b | B26: 행성 × 하우스 (목성·토성·천왕성·해왕성·명왕성) | C26: 출생차트 휠 행성 탭 시트 (정확도 A·B등급만) | D26: =COUNTA('B2b 행성 × 하우스 (목성·토성·천왕성·해왕성·명왕성'!A2:A61) -> 60 | E26: =COUNTIF('B2b 행성 × 하우스 (목성·토성·천왕성·해왕성·명왕성'!H2:H61,"승인") -> 0 | F26: =COUNTIF('B2b 행성 × 하우스 (목성·토성·천왕성·해왕성·명왕성'!H2:H61,"수정필요") -> 0 | G26: =COUNTIF('B2b 행성 × 하우스 (목성·토성·천왕성·해왕성·명왕성'!H2:H61,"삭제") -> 0 | H26: =COUNTIF('B2b 행성 × 하우스 (목성·토성·천왕성·해왕성·명왕성'!H2:H61,"미검수") -> 60 | I26: =IFERROR((E26+G26)/D26,0) -> 0
A27: B3 | B27: 출생차트 주요 각도 | C27: 출생차트 휠 선 탭 시트, 캐릭터 근거 보조 | D27: =COUNTA('B3 출생차트 주요 각도'!A2:A64) -> 63 | E27: =COUNTIF('B3 출생차트 주요 각도'!I2:I64,"승인") -> 0 | F27: =COUNTIF('B3 출생차트 주요 각도'!I2:I64,"수정필요") -> 0 | G27: =COUNTIF('B3 출생차트 주요 각도'!I2:I64,"삭제") -> 0 | H27: =COUNTIF('B3 출생차트 주요 각도'!I2:I64,"미검수") -> 63 | I27: =IFERROR((E27+G27)/D27,0) -> 0
A28: B6 | B28: 캐릭터 후보 선택 카드 | C28: 동점·시간대(B·C등급) 후보 확인 화면 '요즘의 나와 더 가까운 건?' | D28: =COUNTA('B6 캐릭터 후보 선택 카드'!A2:A21) -> 20 | E28: =COUNTIF('B6 캐릭터 후보 선택 카드'!G2:G21,"승인") -> 0 | F28: =COUNTIF('B6 캐릭터 후보 선택 카드'!G2:G21,"수정필요") -> 0 | G28: =COUNTIF('B6 캐릭터 후보 선택 카드'!G2:G21,"삭제") -> 0 | H28: =COUNTIF('B6 캐릭터 후보 선택 카드'!G2:G21,"미검수") -> 20 | I28: =IFERROR((E28+G28)/D28,0) -> 0
A29: B7 | B29: 놓아줄 것·키울 것 (캐릭터별) | C29: 2027 마음가짐 '• 놓아줄 것', '• 키울 것' 문단의 뼈대(AI는 Q3 바람과 잇기만) | D29: =COUNTA('B7 놓아줄 것·키울 것 (캐릭터별)'!A2:A21) -> 20 | E29: =COUNTIF('B7 놓아줄 것·키울 것 (캐릭터별)'!F2:F21,"승인") -> 0 | F29: =COUNTIF('B7 놓아줄 것·키울 것 (캐릭터별)'!F2:F21,"수정필요") -> 0 | G29: =COUNTIF('B7 놓아줄 것·키울 것 (캐릭터별)'!F2:F21,"삭제") -> 0 | H29: =COUNTIF('B7 놓아줄 것·키울 것 (캐릭터별)'!F2:F21,"미검수") -> 20 | I29: =IFERROR((E29+G29)/D29,0) -> 0
A30: B8 | B30: 고민 영역(Q1) 안내 | C30: 연말·2027 파트 도입 연결, 고민 영역 이벤트 없을 때 | D30: =COUNTA('B8 고민 영역(Q1) 안내'!A2:A7) -> 6 | E30: =COUNTIF('B8 고민 영역(Q1) 안내'!I2:I7,"승인") -> 0 | F30: =COUNTIF('B8 고민 영역(Q1) 안내'!I2:I7,"수정필요") -> 0 | G30: =COUNTIF('B8 고민 영역(Q1) 안내'!I2:I7,"삭제") -> 0 | H30: =COUNTIF('B8 고민 영역(Q1) 안내'!I2:I7,"미검수") -> 6 | I30: =IFERROR((E30+G30)/D30,0) -> 0
A31: B9 | B31: 움직임 × 기질 문장 | C31: 2027 마음가짐 판정 뒤 한 문장, 5년 표 움직임 배지 설명, 타임라인 범례 | D31: =COUNTA('B9 움직임 × 기질 문장'!A2:A13) -> 12 | E31: =COUNTIF('B9 움직임 × 기질 문장'!H2:H13,"승인") -> 0 | F31: =COUNTIF('B9 움직임 × 기질 문장'!H2:H13,"수정필요") -> 0 | G31: =COUNTIF('B9 움직임 × 기질 문장'!H2:H13,"삭제") -> 0 | H31: =COUNTIF('B9 움직임 × 기질 문장'!H2:H13,"미검수") -> 12 | I31: =IFERROR((E31+G31)/D31,0) -> 0
A32: B10 | B32: 경계 구간 문장 (판정 기준선 ±1) | C32: 2027 판정 문단·5년 본문과 표 칸 뒤 배지. 엔진 label()의 edge_db 값으로 선택 | D32: =COUNTA('B10 경계 구간 문장 (판정 기준선 ±1)'!A2:A5) -> 4 | E32: =COUNTIF('B10 경계 구간 문장 (판정 기준선 ±1)'!H2:H5,"승인") -> 0 | F32: =COUNTIF('B10 경계 구간 문장 (판정 기준선 ±1)'!H2:H5,"수정필요") -> 0 | G32: =COUNTIF('B10 경계 구간 문장 (판정 기준선 ±1)'!H2:H5,"삭제") -> 0 | H32: =COUNTIF('B10 경계 구간 문장 (판정 기준선 ±1)'!H2:H5,"미검수") -> 4 | I32: =IFERROR((E32+G32)/D32,0) -> 0
A33: B11 | B33: 요약 문장 틀·화면 고정 문구 (2026-10-09) | C33: 섹션 2~7 첫 문장(굵게), 연말 조심할 것 표현, 소제목, 2027 흐름 단계, 저장·로그인, 결제 팝업 | D33: =COUNTA('B11 요약 문장 틀·화면 고정 문구 (2026-10-0'!A2:A30) -> 29 | E33: =COUNTIF('B11 요약 문장 틀·화면 고정 문구 (2026-10-0'!F2:F30,"승인") -> 0 | F33: =COUNTIF('B11 요약 문장 틀·화면 고정 문구 (2026-10-0'!F2:F30,"수정필요") -> 0 | G33: =COUNTIF('B11 요약 문장 틀·화면 고정 문구 (2026-10-0'!F2:F30,"삭제") -> 0 | H33: =COUNTIF('B11 요약 문장 틀·화면 고정 문구 (2026-10-0'!F2:F30,"미검수") -> 29 | I33: =IFERROR((E33+G33)/D33,0) -> 0
A34: B12 | B34: 바람과 흐름 잇기 — AI 대체 문장 | C34: 5번(2027)·6번(5년) 섹션 판정 문단 바로 뒤. 평소에는 AI가 4문장을 쓰고(06 프롬프트 wish_bridge_2027 / wish_bridge_5y), 검증 실패·시간 초과일 때 이 문장을 쓴다 | D34: =COUNTA('B12 바람과 흐름 잇기 — AI 대체 문장'!A2:A23) -> 22 | E34: =COUNTIF('B12 바람과 흐름 잇기 — AI 대체 문장'!G2:G23,"승인") -> 0 | F34: =COUNTIF('B12 바람과 흐름 잇기 — AI 대체 문장'!G2:G23,"수정필요") -> 0 | G34: =COUNTIF('B12 바람과 흐름 잇기 — AI 대체 문장'!G2:G23,"삭제") -> 0 | H34: =COUNTIF('B12 바람과 흐름 잇기 — AI 대체 문장'!G2:G23,"미검수") -> 22 | I34: =IFERROR((E34+G34)/D34,0) -> 0
A35: C1 | B35: 금지어·대체어 사전 (자동 검증용) | C35: validate: DB 문장 검수 + AI 출력 검증. 데이터(문장 아님) | D35: =COUNTA('C1 금지어·대체어 사전 (자동 검증용)'!A2:A80) -> 79 | E35: =COUNTIF('C1 금지어·대체어 사전 (자동 검증용)'!H2:H80,"승인") -> 0 | F35: =COUNTIF('C1 금지어·대체어 사전 (자동 검증용)'!H2:H80,"수정필요") -> 0 | G35: =COUNTIF('C1 금지어·대체어 사전 (자동 검증용)'!H2:H80,"삭제") -> 0 | H35: =COUNTIF('C1 금지어·대체어 사전 (자동 검증용)'!H2:H80,"미검수") -> 79 | I35: =IFERROR((E35+G35)/D35,0) -> 0
A36: C2 | B36: 점수·가중치 설정 (엔진용 데이터) | C36: 이벤트 순위, Q1 가산, 바람 이루어짐·움직임·기질. v3 (2026-10-08) — 파일럿 후 조정 | D36: =COUNTA('C2 점수·가중치 설정 (엔진용 데이터)'!A2:A69) -> 68 | E36: =COUNTIF('C2 점수·가중치 설정 (엔진용 데이터)'!G2:G69,"승인") -> 0 | F36: =COUNTIF('C2 점수·가중치 설정 (엔진용 데이터)'!G2:G69,"수정필요") -> 0 | G36: =COUNTIF('C2 점수·가중치 설정 (엔진용 데이터)'!G2:G69,"삭제") -> 0 | H36: =COUNTIF('C2 점수·가중치 설정 (엔진용 데이터)'!G2:G69,"미검수") -> 68 | I36: =IFERROR((E36+G36)/D36,0) -> 0
A37: 합계 | D37: =SUM(D2:D36) -> 1366 | E37: =SUM(E2:E36) -> 0 | F37: =SUM(F2:F36) -> 0 | G37: =SUM(G2:G36) -> 0 | H37: =SUM(H2:H36) -> 1366 | I37: =IFERROR((E37+G37)/D37,0) -> 0

Sheet A1 별자리 기본 정보
A1: ID | B1: 별자리 | C1: 영문명 | D1: 기호 | E1: 태양 기간(대략) | F1: 원소 | G1: 성질 | H1: 수호성 | I1: 키워드 | J1: 한 줄 소개 | K1: 별자리 칸 탭 설명 | L1: 검수 메모 | M1: 검수상태 | N1: 수정 문장 | O1: 상담사 메모
A2: SIGN_ARIES | B2: 양자리 | C2: Aries | D2: ♈ | E2: 3월 21일~4월 19일 | F2: 불 | G2: 활동 | H2: 화성 | I2: 시작 · 용기 · 직진 | J2: 먼저 불을 붙이고 부딪히며 길을 여는 별자리예요. | K2: 양자리는 열두 별자리의 첫 번째 자리로, 무언가를 처음 시작하는 기운을 상징합니다. 망설이기보다 일단 움직이고, 몸으로 부딪히며 배우는 힘이에요. | L2: dates 칸은 안내용 대략값입니다. 태양이 별자리를 옮기는 날은 해마다 하루 정도 달라지므로, 실제 별자리 판정은 엔진 계산값을 따르고 경계일 출생자에게 이 날짜를 근거로 설명하지 않도록 해 주세요. | M2: 미검수
A3: SIGN_TAURUS | B3: 황소자리 | C3: Taurus | D3: ♉ | E3: 4월 20일~5월 20일 | F3: 흙 | G3: 고정 | H3: 금성 | I3: 안정 · 감각 · 꾸준함 | J3: 천천히, 하지만 한번 뿌리내리면 오래가는 별자리입니다. | K3: 황소자리는 손에 잡히는 안정과 몸의 감각을 소중히 여기는 기운이에요. 맛있는 밥, 익숙한 공간, 꾸준히 쌓아 온 것에서 힘을 얻는 자리입니다. | M3: 미검수
A4: SIGN_GEMINI | B4: 쌍둥이자리 | C4: Gemini | D4: ♊ | E4: 5월 21일~6월 21일 | F4: 공기 | G4: 변통 | H4: 수성 | I4: 호기심 · 대화 · 연결 | J4: 궁금한 것을 묻고 잇고 전하며 세상을 넓히는 별자리예요. | K4: 쌍둥이자리는 생각과 말, 정보가 빠르게 오가는 기운을 상징합니다. 한 가지에 머물기보다 여러 이야기를 연결하며 가볍게 움직일 때 살아나요. | M4: 미검수
A5: SIGN_CANCER | B5: 게자리 | C5: Cancer | D5: ♋ | E5: 6월 22일~7월 22일 | F5: 물 | G5: 활동 | H5: 달 | I5: 돌봄 · 소속감 · 보호 | J5: 내 사람과 내 자리를 따뜻하게 지키는 별자리입니다. | K5: 게자리는 품고 돌보는 기운, 마음이 돌아갈 집을 상징해요. 단단한 껍질 안에 여린 속을 지니고 있어, 안전하다고 느끼는 곳에서 가장 다정해집니다. | M5: 미검수
A6: SIGN_LEO | B6: 사자자리 | C6: Leo | D6: ♌ | E6: 7월 23일~8월 22일 | F6: 불 | G6: 고정 | H6: 태양 | I6: 표현 · 자부심 · 온기 | J6: 자기만의 빛을 드러내고 주변을 환하게 데우는 별자리예요. | K6: 사자자리는 나를 표현하고 마음껏 빛나고 싶은 기운을 상징합니다. 무대 위의 자신감뿐 아니라, 소중한 사람에게 아낌없이 내어 주는 너그러움도 이 자리의 힘이에요. | M6: 미검수
A7: SIGN_VIRGO | B7: 처녀자리 | C7: Virgo | D7: ♍ | E7: 8월 23일~9월 22일 | F7: 흙 | G7: 변통 | H7: 수성 | I7: 정리 · 섬세함 · 쓸모 | J7: 작은 것을 살피고 다듬어 더 낫게 만드는 별자리입니다. | K7: 처녀자리는 흩어진 것을 분류하고 고치고 다듬는 기운이에요. 눈에 잘 띄지 않는 일상의 디테일에서 쓸모를 찾아내는 성실함을 상징합니다. | M7: 미검수
A8: SIGN_LIBRA | B8: 천칭자리 | C8: Libra | D8: ♎ | E8: 9월 23일~10월 22일 | F8: 공기 | G8: 활동 | H8: 금성 | I8: 균형 · 관계 · 아름다움 | J8: 서로의 마음이 기울지 않도록 균형을 맞추는 별자리예요. | K8: 천칭자리는 나와 너 사이의 균형, 조화로운 관계를 상징합니다. 공정함과 아름다움을 중요하게 여기고, 함께할 때 더 좋은 답을 찾는 기운이에요. | M8: 미검수
A9: SIGN_SCORPIO | B9: 전갈자리 | C9: Scorpio | D9: ♏ | E9: 10월 23일~11월 21일 | F9: 물 | G9: 고정 | H9: 명왕성(전통: 화성) | I9: 깊이 · 집중 · 변형 | J9: 얕게 머물지 않고 끝까지 파고드는 별자리입니다. | K9: 전갈자리는 겉보다 속, 넓이보다 깊이를 향하는 기운이에요. 한번 마음을 주면 깊게 연결되고, 무너진 자리에서 다시 일어서는 힘을 상징합니다. | L9: 수호성은 현대 기준(명왕성)을 앞에, 전통 수호성(화성)을 괄호에 적었습니다. 물병자리·물고기자리도 같은 방식입니다. 화면에 하나만 노출할지 확인 부탁드립니다. | M9: 미검수
A10: SIGN_SAGITTARIUS | B10: 사수자리 | C10: Sagittarius | D10: ♐ | E10: 11월 22일~12월 21일 | F10: 불 | G10: 변통 | H10: 목성 | I10: 탐험 · 자유 · 의미 | J10: 더 넓은 세상과 더 큰 의미를 향해 활을 쏘는 별자리예요. | K10: 사수자리는 멀리 가 보고, 배우고, 나만의 믿음을 찾아가는 기운을 상징합니다. 낙천적인 시선으로 익숙한 경계를 넘어설 때 살아나는 자리예요. | M10: 미검수
A11: SIGN_CAPRICORN | B11: 염소자리 | C11: Capricorn | D11: ♑ | E11: 12월 22일~1월 19일 | F11: 흙 | G11: 활동 | H11: 토성 | I11: 책임 · 인내 · 성취 | J11: 긴 시간을 들여 한 계단씩 정상에 오르는 별자리입니다. | K11: 염소자리는 목표를 세우고 차근차근 쌓아 올리는 기운이에요. 당장의 성과보다 오래 버티는 구조와 믿을 만한 결과를 중요하게 여기는 자리입니다. | M11: 미검수
A12: SIGN_AQUARIUS | B12: 물병자리 | C12: Aquarius | D12: ♒ | E12: 1월 20일~2월 18일 | F12: 공기 | G12: 고정 | H12: 천왕성(전통: 토성) | I12: 독립 · 새로움 · 공동체 | J12: 익숙한 틀 밖에서 새로운 방식을 떠올리는 별자리예요. | K12: 물병자리는 남과 다른 생각, 더 나은 미래를 향한 기운을 상징합니다. 개인의 자유를 지키면서도 여럿이 함께 잘 사는 방법을 고민하는 자리예요. | M12: 미검수
A13: SIGN_PISCES | B13: 물고기자리 | C13: Pisces | D13: ♓ | E13: 2월 19일~3월 20일 | F13: 물 | G13: 변통 | H13: 해왕성(전통: 목성) | I13: 공감 · 상상 · 흐름 | J13: 경계 없이 스며들며 남의 마음을 느끼는 별자리입니다. | K13: 물고기자리는 열두 별자리의 마지막 자리로, 경계를 풀고 하나로 녹아드는 기운이에요. 공감과 상상력, 말로 다 설명되지 않는 감각을 상징합니다. | M13: 미검수

Sheet A2 태양 × 별자리
A1: ID | B1: 별자리 | C1: 표 한 줄 해석 | D1: 본문 | E1: 지나칠 때 | F1: 검수 메모 | G1: 검수상태 | H1: 수정 문장 | I1: 상담사 메모
A2: SUN_ARIES | B2: 양자리 | C2: 먼저 시작하고 부딪히며 배우는 사람이에요. 새로운 도전 앞에서 가장 살아 있다고 느낍니다. | D2: 나를 움직이는 건 ‘해 보고 싶다’는 순수한 의욕입니다. 회의에서 아무도 손들지 않을 때 먼저 ‘제가 해 볼게요’라고 말하는 쪽이 당신일 때가 많아요. 속도가 붙을 때 오히려 머리가 맑아지는 사람입니다. | E2: 마음이 급해지면 끝까지 듣기 전에 결론부터 내려 버리기 쉬워요. | G2: 미검수
A3: SUN_TAURUS | B3: 황소자리 | C3: 천천히 쌓아 올린 안정 위에서 힘을 내는 사람입니다. 내 속도와 감각을 믿을 때 가장 단단해져요. | D3: 나를 움직이는 건 손에 잡히는 결과와 오래가는 편안함이에요. 퇴근길에 좋아하는 빵집에 들러 늘 사던 빵을 고르는 작은 습관이 하루를 지탱해 주기도 합니다. 한번 정한 일은 묵묵히 끝까지 해내는 꾸준함이 큰 무기예요. | E3: 익숙함을 지키려다 꼭 필요한 변화까지 미뤄 둘 때가 있어요. | G3: 미검수
A4: SUN_GEMINI | B4: 쌍둥이자리 | C4: 궁금한 것을 따라가며 생각과 사람을 연결하는 사람이에요. 새로운 이야기가 오갈 때 에너지가 차오릅니다. | D4: 나를 움직이는 건 ‘이건 왜 그럴까?’ 하는 호기심입니다. 점심시간에 들은 이야기를 저녁에 찾아보고, 다음 날 누군가에게 신나게 전해 주는 장면이 자연스러워요. 머릿속에 창이 여러 개 열려 있을 때 오히려 생기가 돕니다. | E4: 관심이 여러 곳으로 흩어지면 마무리 직전에 흥미가 식기도 해요. | G4: 미검수
A5: SUN_CANCER | B5: 게자리 | C5: 아끼는 사람과 머물 곳을 지키는 데서 힘이 나는 사람입니다. 누군가를 챙길 때 마음이 가장 단단해져요. | D5: 나를 움직이는 건 ‘내 사람들이 편안했으면’ 하는 마음이에요. 친구가 지나가듯 한 말을 기억해 두었다가 다음 만남에 작은 간식을 챙겨 가는 다정함이 자연스럽습니다. 돌아갈 자리가 든든할수록 바깥에서도 용감해져요. | E5: 남을 챙기느라 정작 내 마음의 허기는 뒤로 미루기 쉽습니다. | G5: 미검수
A6: SUN_LEO | B6: 사자자리 | C6: 나다운 빛을 드러내고 누군가 알아봐 줄 때 살아나는 사람이에요. 진심을 다해 표현하는 것이 삶의 큰 동력입니다. | D6: 나를 움직이는 건 ‘이건 내가 만든 거야’라고 말할 수 있는 자부심입니다. 발표 자료 한 장도 그냥 넘기지 않고 내 색을 입혀야 마음이 놓이는 편이에요. 주변을 즐겁게 만들 때 스스로도 가장 따뜻해집니다. | E6: 애쓴 만큼 알아봐 주지 않으면 서운함이 생각보다 오래 남을 수 있어요. | G6: 미검수
A7: SUN_VIRGO | B7: 처녀자리 | C7: 작은 것을 다듬어 더 쓸모 있게 만드는 사람입니다. 내가 도움이 되고 있다는 감각이 큰 힘이 돼요. | D7: 나를 움직이는 건 ‘조금 더 낫게 할 수 있겠다’ 하는 눈썰미예요. 남들이 지나치는 표의 오타나 일정의 빈틈을 먼저 발견하고 조용히 고쳐 두곤 합니다. 정돈된 할 일 목록을 하나씩 지워 갈 때 하루가 개운해져요. | E7: 완성도를 높이려다 스스로에게 지나치게 엄격해지기 쉬워요. | G7: 미검수
A8: SUN_LIBRA | B8: 천칭자리 | C8: 관계 속에서 균형과 조화를 만들어 가는 사람이에요. 함께여서 더 좋은 답을 찾을 때 빛이 납니다. | D8: 나를 움직이는 건 모두가 납득할 수 있는 공정함과 아름다움입니다. 단체 메뉴를 정할 때 조용히 모두의 취향을 살펴 가장 무난한 곳을 제안하는 사람이 당신일 수 있어요. 공간과 분위기가 조화로울 때 생각도 한결 맑아집니다. | E8: 모두를 만족시키려다 내 마음이 어느 쪽인지 놓칠 때가 있습니다. | G8: 미검수
A9: SUN_SCORPIO | B9: 전갈자리 | C9: 한번 마음먹은 것에 깊이 몰입하는 사람입니다. 진짜를 알아낼 때까지 파고드는 힘이 삶의 중심이에요. | D9: 나를 움직이는 건 겉으로 보이는 것 너머의 진심을 알고 싶은 마음이에요. 넓게 아는 사람 열 명보다 속 깊은 이야기를 나누는 한 사람이 더 소중하게 느껴지는 편입니다. 쉽게 드러내지 않지만, 한번 집중하면 끝까지 가는 힘이 있어요. | E9: 믿음이 흔들리면 마음의 문을 한꺼번에 닫아 버리기 쉬워요. | G9: 미검수
A10: SUN_SAGITTARIUS | B10: 사수자리 | C10: 더 넓은 세상과 의미를 찾아 나아가는 사람이에요. 배우고 떠나고 넓어질 때 가장 생기가 돕니다. | D10: 나를 움직이는 건 ‘저 너머에는 뭐가 있을까’ 하는 탐험심입니다. 주말에 가 보지 않은 동네를 걷거나 새 분야의 책을 집어 드는 일이 큰 충전이 돼요. 어려운 상황에서도 웃을 거리를 찾아내는 낙천성이 주변까지 밝힙니다. | E10: 자유를 지키려다 약속과 마무리를 가볍게 넘길 때가 있어요. | G10: 미검수
A11: SUN_CAPRICORN | B11: 염소자리 | C11: 목표를 세우고 한 계단씩 쌓아 올리는 사람입니다. 믿을 만한 결과를 만들어 낼 때 마음이 단단해져요. | D11: 나를 움직이는 건 오래 남는 성취와 책임을 다했다는 감각이에요. 남들이 손을 놓은 일도 일정표를 다시 짜서 끝까지 끌고 가는 끈기가 있습니다. 시간이 갈수록 더 깊은 신뢰를 얻는 사람이에요. | E11: 해야 할 일에 몰두하다 쉬는 것까지 숙제처럼 느끼기 쉬워요. | G11: 미검수
A12: SUN_AQUARIUS | B12: 물병자리 | C12: 남과 다른 시선으로 더 나은 방식을 떠올리는 사람이에요. 나답게 자유로울 때 가장 큰 힘이 납니다. | D12: 나를 움직이는 건 ‘꼭 이렇게 해야 할까?’ 하는 물음입니다. 모두가 당연하게 따르던 방식에 새로운 도구나 규칙을 제안해 흐름을 바꾸곤 해요. 저마다의 개성을 지키면서도 함께 잘 지내는 방법에 관심이 많습니다. | E12: 감정보다 생각이 앞서면 가까운 사람에게 거리감을 주기 쉽습니다. | G12: 미검수
A13: SUN_PISCES | B13: 물고기자리 | C13: 다른 사람의 마음을 섬세하게 느끼고 품어 주는 사람입니다. 상상하고 공감할 때 삶이 풍성해져요. | D13: 나를 움직이는 건 말로 다 설명되지 않는 마음의 울림이에요. 좋아하는 노래 한 곡에 하루의 기분이 바뀌고, 친구의 표정만 보고도 무슨 일이 있는지 알아채곤 합니다. 경계를 부드럽게 녹이는 상상력이 큰 재능입니다. | E13: 남의 감정을 너무 깊이 받아들여 내 경계가 흐려지기 쉬워요. | G13: 미검수

Sheet A3 달 × 별자리
A1: ID | B1: 별자리 | C1: 표 한 줄 해석 | D1: 본문 | E1: 마음이 지칠 때 | F1: 검수 메모 | G1: 검수상태 | H1: 수정 문장 | I1: 상담사 메모
A2: MOON_ARIES | B2: 양자리 | C2: 감정이 빠르고 솔직하게 올라오는 편이에요. 바로 표현하고 움직일 수 있을 때 마음이 풀립니다. | D2: 화가 나거나 속상하면 오래 담아 두기보다 그 자리에서 꺼내고 금방 털어 내는 편입니다. 답답한 날에는 생각을 정리하기보다 빠르게 걷거나 몸을 움직이는 쪽이 더 효과가 있어요. 내 뜻대로 움직일 수 있는 여지가 있을 때 감정도 안정됩니다. | E2: 땀이 살짝 날 만큼 몸을 움직이고 나면 엉킨 마음이 한결 가벼워져요. | G2: 미검수
A3: MOON_TAURUS | B3: 황소자리 | C3: 익숙한 리듬과 편안한 감각 속에서 마음이 놓여요. 급하게 바뀌지 않는 일상이 안정의 기준입니다. | D3: 감정이 흔들려도 겉으로는 잘 드러나지 않고, 천천히 소화하는 편이에요. 따뜻한 밥 한 끼, 포근한 이불, 늘 가던 산책길 같은 감각이 마음을 가장 빨리 진정시킵니다. 갑작스러운 변화 앞에서는 받아들일 시간이 조금 더 필요해요. | E3: 좋아하는 음식과 익숙한 공간에서 천천히 쉬는 시간이 회복을 돕습니다. | G3: 미검수
A4: MOON_GEMINI | B4: 쌍둥이자리 | C4: 마음을 말로 꺼내고 나눌 때 한결 편해져요. 생각이 오갈 여유가 있어야 감정도 숨을 쉽니다. | D4: 속상한 일이 생기면 누군가에게 이야기하거나 글로 적으면서 감정을 이해하는 편입니다. 메신저로 친구와 수다를 떨다 보면 어느새 고민이 정리되어 있기도 해요. 같은 자리에 오래 갇혀 있으면 마음이 답답해지기 쉽습니다. | E4: 머릿속 생각을 종이에 쏟아 내거나 믿는 사람과 가볍게 대화해 보세요. | G4: 미검수
A5: MOON_CANCER | B5: 게자리 | C5: 아끼는 사람과 내 공간이 안전할 때 마음이 편해져요. 돌보고 돌봄 받는 관계가 안정의 뿌리입니다. | D5: 감정을 깊고 섬세하게 느끼고, 분위기의 작은 변화도 금방 알아채는 편입니다. 지친 날에는 집에 돌아와 익숙한 음식을 해 먹는 것만으로 마음이 데워지기도 해요. 서운함을 바로 말하기보다 속으로 품는 편이라, 안전한 상대가 곁에 있는 것이 중요합니다. | E5: 편안한 사람과 집밥 같은 따뜻한 시간을 보내면 마음이 차오릅니다. | G5: 미검수
A6: MOON_LEO | B6: 사자자리 | C6: 내 마음이 진심으로 받아들여질 때 편안해져요. 따뜻한 관심과 반응이 감정의 연료입니다. | D6: 기쁨도 서운함도 크고 분명하게 느끼는 편이에요. 내가 준비한 작은 선물에 상대가 환하게 웃어 줄 때 하루의 피로가 풀리기도 합니다. 마음이 상했을 때는 자존심 때문에 괜찮은 척하기 쉬워서, 솔직하게 말할 수 있는 자리가 필요해요. | E6: 나를 즐겁게 하는 취미에 푹 빠지는 시간이 마음에 다시 불을 켜 줍니다. | G6: 미검수
A7: MOON_VIRGO | B7: 처녀자리 | C7: 주변이 정돈되고 할 일이 보일 때 마음이 놓여요. 걱정은 정리하고 고치는 방식으로 다루는 편입니다. | D7: 불안한 마음이 들면 할 일을 적어 보거나 책상을 치우면서 감정을 가라앉히는 편이에요. 누군가 힘들어할 때 위로의 말보다 실질적으로 손을 보태는 것으로 마음을 표현합니다. 다만 스스로를 점검하는 목소리가 커지면 쉬어도 쉬는 것 같지 않을 수 있어요. | E7: 작은 공간 하나를 정리하고 오늘 해낸 일을 적어 보면 마음이 가라앉습니다. | G7: 미검수
A8: MOON_LIBRA | B8: 천칭자리 | C8: 주변 관계가 평화롭고 조화로울 때 마음이 놓입니다. 어긋난 관계가 있으면 마음 한구석이 계속 편치 않아요. | D8: 감정을 혼자 삭이기보다 누군가와 나누고 대화하면서 균형을 찾는 편이에요. 다툼이 생기면 내 기분보다 분위기를 먼저 살피고 서둘러 화해의 말을 꺼내기도 합니다. 좋은 음악이나 정돈된 공간처럼 조화로운 환경도 마음을 진정시켜 줘요. | E8: 마음이 맞는 사람과 차 한잔하거나 아름다운 것을 보며 쉬어 보세요. | G8: 미검수
A9: MOON_SCORPIO | B9: 전갈자리 | C9: 깊이 믿을 수 있는 사람이 곁에 있을 때 마음이 놓여요. 감정을 얕게 나누기보다 깊게 연결되고 싶어 합니다. | D9: 감정을 강하게 느끼지만 쉽게 드러내지 않고, 속에서 오래 소화하는 편입니다. 상처받은 일은 겉으로 넘어간 것처럼 보여도 마음속에서 여러 번 곱씹기도 해요. 온전히 믿는 사람 앞에서야 비로소 속마음을 꺼내 놓습니다. | E9: 혼자만의 시간에 감정을 충분히 느끼고 글로 흘려보내는 것이 도움이 돼요. | G9: 미검수
A10: MOON_SAGITTARIUS | B10: 사수자리 | C10: 자유롭게 움직이고 새로운 것을 경험할 때 마음이 가벼워져요. 답답하게 묶여 있으면 감정도 무거워집니다. | D10: 힘든 일이 있어도 의미를 찾아 웃으며 넘기려는 낙천성이 있는 편입니다. 마음이 꽉 막힌 날에는 무작정 버스를 타고 낯선 동네에 가 보는 것만으로 숨통이 트이기도 해요. 다만 무거운 감정을 너무 빨리 넘기면 나중에 한꺼번에 밀려올 수 있습니다. | E10: 짧은 나들이나 새로운 배움처럼 시야를 넓혀 주는 경험이 마음을 풀어 줘요. | G10: 미검수
A11: MOON_CAPRICORN | B11: 염소자리 | C11: 상황을 내가 감당하고 있다는 느낌이 들 때 마음이 놓여요. 감정보다 해야 할 일을 먼저 챙기는 편입니다. | D11: 속상해도 먼저 할 일을 처리하고, 감정은 나중에 혼자 다루는 편이에요. 힘들다는 말을 꺼내기보다 묵묵히 버티는 쪽이 익숙합니다. 안정된 계획과 예측할 수 있는 일정이 있을 때 마음도 조용히 단단해져요. | E11: 해낸 일을 스스로 인정해 주고, 일과 상관없는 쉬는 시간을 미리 정해 두세요. | G11: 미검수
A12: MOON_AQUARIUS | B12: 물병자리 | C12: 내 공간과 생각의 자유가 지켜질 때 마음이 편해져요. 감정을 한 걸음 떨어져서 바라보는 편입니다. | D12: 감정이 크게 일어나면 먼저 거리를 두고 차분히 이해해 보려는 편이에요. 가까운 사이일수록 너무 붙어 있기보다 각자의 시간을 존중할 때 더 편안함을 느낍니다. 생각이 통하는 친구들과의 느슨한 연결이 든든한 안전망이 돼요. | E12: 혼자만의 시간을 지키면서 생각이 통하는 사람과 가볍게 연결돼 있는 것이 힘이 됩니다. | G12: 미검수
A13: MOON_PISCES | B13: 물고기자리 | C13: 마음이 조용히 흐를 수 있는 여유가 있을 때 편안해져요. 주변의 감정을 스펀지처럼 흡수하는 편입니다. | D13: 다른 사람의 기분을 내 것처럼 느끼고, 슬픈 영화 한 편에도 깊이 젖어 드는 편이에요. 지친 날에는 음악을 들으며 멍하니 있거나 물가를 걷는 시간이 마음을 씻어 줍니다. 사람 많은 곳에 오래 있으면 나도 모르게 에너지가 빠져나가기 쉬워요. | E13: 음악, 따뜻한 목욕, 물가 산책처럼 감각을 부드럽게 쉬게 하는 시간이 도움이 됩니다. | G13: 미검수

Sheet A4 상승궁 × 별자리
A1: ID | B1: 별자리 | C1: 표 한 줄 해석 | D1: 본문 | E1: 검수 메모 | F1: 검수상태 | G1: 수정 문장 | H1: 상담사 메모
A2: ASC_ARIES | B2: 양자리 | C2: 에너지 넘치고 시원시원한 사람으로 보여요. 망설이기보다 먼저 행동으로 세상에 다가갑니다. | D2: 처음 만난 자리에서도 먼저 말을 걸거나 분위기를 이끄는 모습이 눈에 띄는 편입니다. 걸음이 빠르고 표정이 솔직해서 생각이 얼굴에 잘 드러나요. 새로운 환경에 금방 뛰어드는 힘이 이 상승궁의 강점입니다. | E2: 출생 시간을 알 때(정확도 A·B등급)만 노출되는 행입니다. 첫인상 묘사가 외모 평가로 읽히지 않도록 분위기·태도 중심으로 썼습니다. | F2: 미검수
A3: ASC_TAURUS | B3: 황소자리 | C3: 차분하고 편안한 사람으로 보여요. 서두르지 않고 내 속도로 세상과 관계를 맺습니다. | D3: 처음에는 말수가 적어 보여도 곁에 있으면 안정감을 주는 사람이라는 인상을 남깁니다. 옷이나 소품, 향처럼 감각적인 취향이 자연스럽게 드러나는 편이에요. 낯선 환경에는 천천히 적응하지만, 한번 익숙해지면 그 자리를 오래 지킵니다. | F3: 미검수
A4: ASC_GEMINI | B4: 쌍둥이자리 | C4: 가볍고 호기심 많은 사람으로 보여요. 말이 잘 통하고 새 정보에 빠르게 반응합니다. | D4: 처음 만난 사람과도 금방 대화의 실마리를 찾아내는 재치가 있는 편입니다. 표정과 손짓이 풍부해서 경쾌하고 젊은 분위기라는 말을 듣기도 해요. 여러 사람과 두루 어울리며 자리를 부드럽게 만드는 힘이 있습니다. | F4: 미검수
A5: ASC_CANCER | B5: 게자리 | C5: 부드럽고 다정한 사람으로 보여요. 낯선 곳에서는 조심스럽게 살핀 뒤 마음을 엽니다. | D5: 처음에는 조금 수줍어 보여도 상대를 편하게 해 주는 따뜻한 분위기가 있는 편입니다. 모임에서 혼자 있는 사람을 먼저 챙기는 세심함이 자연스럽게 드러나요. 안전하다고 느끼면 그때부터 웃음이 많아지고 마음을 활짝 엽니다. | F5: 미검수
A6: ASC_LEO | B6: 사자자리 | C6: 존재감 있고 밝은 사람으로 보여요. 당당하게 나를 드러내며 세상을 마주합니다. | D6: 들어서는 순간 분위기가 환해진다는 말을 듣기 쉬운 인상입니다. 옷차림이나 말투에 나만의 개성이 묻어나고, 자연스럽게 시선을 모으는 편이에요. 사람들 앞에 설 때 오히려 힘이 나는 상승궁입니다. | F6: 미검수
A7: ASC_VIRGO | B7: 처녀자리 | C7: 단정하고 신중한 사람으로 보여요. 상황을 꼼꼼히 살핀 뒤 필요한 곳에 손을 보탭니다. | D7: 처음에는 조용히 관찰하는 쪽이라 차분하고 성실하다는 인상을 주는 편입니다. 약속 시간을 지키고 필요한 것을 미리 챙겨 오는 작은 습관이 신뢰를 쌓아요. 겉으로는 침착해 보여도 속으로는 세세한 것까지 살피고 있습니다. | F7: 미검수
A8: ASC_LIBRA | B8: 천칭자리 | C8: 상냥하고 세련된 사람으로 보여요. 상대를 배려하며 부드럽게 다가갑니다. | D8: 처음 만난 자리에서도 예의 바르고 편안한 분위기를 만드는 편입니다. 상대의 말에 고개를 끄덕이며 귀 기울이는 모습이 호감을 주기 쉬워요. 부딪히기보다 접점을 먼저 찾는 태도가 첫인상에 자연스럽게 묻어납니다. | F8: 미검수
A9: ASC_SCORPIO | B9: 전갈자리 | C9: 속을 쉽게 알 수 없는, 깊이 있는 사람으로 보여요. 상대를 충분히 살핀 뒤에야 마음을 엽니다. | D9: 말수는 많지 않아도 눈빛과 분위기에서 강한 존재감이 느껴지는 편입니다. 처음에는 거리를 두는 듯 보이지만, 그만큼 신중하게 사람을 알아 가는 중이에요. 한번 마음을 연 상대에게는 누구보다 깊게 곁을 내어 줍니다. | F9: 미검수
A10: ASC_SAGITTARIUS | B10: 사수자리 | C10: 밝고 개방적인 사람으로 보여요. 낯선 사람과 새로운 경험에 거리낌 없이 다가갑니다. | D10: 솔직하고 유쾌한 말투 덕분에 처음 만난 사람도 금방 편해지는 인상입니다. 여행 이야기나 새로 배운 것을 신나게 나누며 대화의 폭을 넓혀 가는 편이에요. 틀에 얽매이지 않는 자유로운 태도가 첫인상의 매력입니다. | F10: 미검수
A11: ASC_CAPRICORN | B11: 염소자리 | C11: 믿음직하고 어른스러운 사람으로 보여요. 신중하게 거리를 지키며 차근차근 신뢰를 쌓습니다. | D11: 처음에는 진지하고 다가가기 어려워 보일 수 있지만, 맡은 일을 끝까지 해내는 모습에서 신뢰를 얻는 편입니다. 시간이 지날수록 의외의 유머와 따뜻함이 드러나요. 오래 알수록 더 편해지는 사람이라는 말을 듣기 쉽습니다. | F11: 미검수
A12: ASC_AQUARIUS | B12: 물병자리 | C12: 독특하고 자유로운 사람으로 보여요. 친근하지만 자기만의 거리를 지키며 세상과 만납니다. | D12: 누구와도 스스럼없이 이야기하지만, 어딘가 남다른 생각을 가진 사람이라는 인상을 줍니다. 유행보다 내 기준을 따르는 취향이 자연스럽게 드러나는 편이에요. 여럿 속에서도 나만의 색을 잃지 않는 것이 이 상승궁의 힘입니다. | F12: 미검수
A13: ASC_PISCES | B13: 물고기자리 | C13: 부드럽고 몽환적인 사람으로 보여요. 주변 분위기에 섬세하게 결을 맞추며 세상과 만납니다. | D13: 처음 만난 사람도 편하게 속 이야기를 꺼내게 만드는 포근한 분위기가 있는 편입니다. 표정이 부드럽고 상대의 기분에 따라 자연스럽게 말투를 맞춰요. 다만 사람이 많은 자리에서는 금방 지칠 수 있어, 혼자 쉬는 틈이 필요합니다. | F13: 미검수

Sheet A5 캐릭터 20종 (점성술판)
A1: ID | B1: 캐릭터 | C1: 역량 | D1: 방식 | E1: 대응 행성 | F1: 원소 | G1: 이미지 파일 | H1: 유형 한 줄(화면용) | I1: 캐릭터 소개 | J1: 차트 근거 | K1: 강점 | L1: 에너지가 많이 드는 순간 | M1: 작은 돌봄 | N1: 공유 카드 한 줄 | O1: 검수 메모 | P1: 검수상태 | Q1: 수정 문장 | R1: 상담사 메모
A2: CHAR_01_OTTER | B2: 수달 | C2: 기대기 | D2: 다가가기 | E2: 달 | F2: 불 | G2: character-01-otter.png | H2: 누군가에게 기대는 일에 에너지가 많이 들고, 그럴 때 먼저 다가가는 유형 | I2: 수달은 마음이 허전할 때 먼저 물에 뛰어들어 친구에게 장난을 거는 캐릭터예요. 혼자 버티기보다 함께 헤엄치며 온기를 나누는 쪽을 고릅니다. | J2: 감정을 맡는 달이 다섯 행성 가운데 가장 많은 긴장을 받고 있습니다. 그래서 누군가에게 기대는 일이 가장 에너지가 드는 역량이 돼요. 그럴 때 기다리기보다 먼저 연락하고 움직이는 것은 차트에서 불의 기운이 가장 강하기 때문입니다. | K2: 어색함을 먼저 깨고 다가가 주변을 금세 따뜻하게 만드는 힘이 있어요. | L2: 먼저 건넨 연락에 답이 늦으면 혼자 마음이 바빠지는 순간입니다. | M2: 연락을 보내기 전에 지금 내게 필요한 것이 대화인지 쉼인지 한 번 물어봐 주세요. | N2: 먼저 다가가는 용기, 그게 수달의 온기예요 | O2: 관계성 테스트 base_knowledge 원문과 대조 필요 (샘플 리포트 수달 문단과 why_text 동일 — 의도된 기준 문장) | P2: 미검수
A3: CHAR_02_SEA_OTTER | B3: 해달 | C3: 기대기 | D3: 맞춰주기 | E3: 달 | F3: 물 | G3: character-02-sea-otter.png | H3: 누군가에게 기대는 일에 에너지가 많이 들고, 그럴 때 상대에게 맞춰 주는 유형 | I3: 해달은 잠들 때 서로 손을 잡아 떠내려가지 않게 하는 캐릭터입니다. 곁에 있는 이의 물결에 몸을 맞추며 조용히 기대는 법을 알아요. | J3: 마음의 안정을 맡는 달이 다섯 행성 중 가장 많은 긴장을 받고 있어요. 그래서 누군가에게 기대는 일에 가장 큰 에너지가 듭니다. 그때 내 마음보다 상대의 기분을 먼저 살피며 곁을 지키는 것은, 차트에서 물의 기운이 가장 강하기 때문이에요. | K3: 말하지 않아도 상대의 기분을 알아채고 편안한 곁이 되어 주는 힘이 있습니다. | L3: 기대고 싶은 날에도 상대 기분부터 맞추느라 내 이야기를 꺼내지 못하는 순간이에요. | M3: 오늘은 상대 기분 말고 내 기분을 한 단어로 먼저 적어 보세요. | N3: 손잡고 떠 있는 해달처럼, 곁에 있어 줘서 고마워요 | O3: 관계성 테스트 base_knowledge 원문과 대조 필요 (손잡고 자는 장면이 관계성판 해달 설명과 겹치는지) | P3: 미검수
A4: CHAR_03_SEAL | B4: 물범 | C4: 기대기 | D4: 거리두기 | E4: 달 | F4: 공기 | G4: character-03-seal.png | H4: 누군가에게 기대는 일에 에너지가 많이 들고, 그럴 때 한발 물러나 혼자 정리하는 유형 | I4: 물범은 무리 가까이 있으면서도 바위 위에 저만의 자리를 두고 쉬는 캐릭터예요. 마음이 무거운 날엔 물속에 잠겼다가 조용히 고개만 내밀어 바깥을 살핍니다. | J4: 감정의 별인 달이 다섯 행성 가운데 가장 많은 긴장을 받고 있습니다. 그래서 누군가에게 마음을 기대는 일이 가장 에너지가 드는 역량이에요. 그럴 때 바로 기대기보다 혼자 생각을 정리할 시간을 먼저 찾는 것은, 차트에서 공기의 기운이 가장 강하기 때문입니다. | K4: 감정이 차오를 때도 한발 떨어져 차분하게 상황을 바라보는 힘이 있어요. | L4: 위로받고 싶으면서도 괜찮다고 말하고 혼자 바위로 올라가는 순간입니다. | M4: 혼자 정리한 뒤에는 믿는 한 사람에게 그 결론만이라도 짧게 나눠 보세요. | N4: 혼자 쉬다가도 고개 내밀어 줘서 반가워요 | O4: 관계성 테스트 base_knowledge 원문과 대조 필요 (물범·물개 일러스트와 설명이 서로 구분되는지) | P4: 미검수
A5: CHAR_04_BEAVER | B5: 비버 | C5: 기대기 | D5: 조율하기 | E5: 달 | F5: 흙 | G5: character-04-beaver.png | H5: 누군가에게 기대는 일에 에너지가 많이 들고, 그럴 때 현실적으로 따져 조율하는 유형 | I5: 비버는 기대고 싶은 마음이 들면 말보다 먼저 함께 머물 집을 짓는 캐릭터입니다. 나뭇가지를 하나씩 쌓듯 기댈 수 있는 자리를 차근차근 만들어요. | J5: 마음의 안정을 맡는 달이 다섯 행성 가운데 가장 많은 긴장을 받고 있어요. 그래서 누군가에게 기대는 일이 가장 에너지가 드는 역량입니다. 그럴 때 감정을 털어놓기보다 함께할 일과 일정을 현실적으로 맞춰 보는 것은, 차트에서 흙의 기운이 가장 강하기 때문이에요. | K5: 말로만 하지 않고 실제로 기댈 수 있는 생활의 터전을 만드는 힘이 있습니다. | L5: 속상한 마음은 뒤로하고 할 일 목록만 정리하다 혼자 지치는 순간이에요. | M5: 할 일 목록 맨 위에 오늘 기분 나누기를 한 줄 넣어 보세요. | N5: 함께 쉴 보금자리를 짓는 비버, 참 든든해요 | O5: 관계성 테스트 base_knowledge 원문과 대조 필요 | P5: 미검수
A6: CHAR_05_MANDARIN_DUCK | B6: 원앙 | C6: 믿기 | D6: 다가가기 | E6: 토성 | F6: 불 | G6: character-05-mandarin-duck.png | H6: 관계를 믿고 마음을 놓는 일에 에너지가 많이 들고, 그럴 때 먼저 다가가는 유형 | I6: 원앙은 마음이 불안할 때 먼저 다가가 나란히 헤엄치며 곁을 확인하는 캐릭터예요. 함께 있는 시간이 쌓일수록 물결 위의 마음도 고요해집니다. | J6: 책임과 구조를 맡는 토성이 다섯 행성 가운데 가장 많은 긴장을 받고 있습니다. 그래서 관계를 믿고 마음을 놓는 일이 가장 에너지가 드는 역량이에요. 그럴 때 혼자 걱정하기보다 먼저 묻고 표현해 확인하는 것은 차트에서 불의 기운이 가장 강하기 때문입니다. | K6: 아끼는 마음을 숨기지 않고 표현해 관계에 온기를 불어넣는 힘이 있어요. | L6: 확인의 말을 들은 뒤에도 마음이 놓이지 않아 다시 묻고 싶어지는 순간입니다. | M6: 묻고 싶은 마음이 들면 그동안 함께 쌓아 온 장면 세 가지를 떠올려 보세요. | N6: 나란히 헤엄치는 시간, 원앙에게는 보물이에요 | O6: 관계성 테스트 base_knowledge 원문과 대조 필요 (원앙의 금슬 이미지는 문화적 상징 — 실제 생태 사실처럼 쓰지 않았음) | P6: 미검수
A7: CHAR_06_PENGUIN | B7: 펭귄 | C7: 믿기 | D7: 맞춰주기 | E7: 토성 | F7: 물 | G7: character-06-penguin.png | H7: 관계를 믿고 마음을 놓는 일에 에너지가 많이 들고, 그럴 때 상대에게 맞춰 주는 유형 | I7: 펭귄은 추운 날 서로 몸을 붙이고 번갈아 바깥 자리를 맡는 캐릭터입니다. 수많은 목소리 가운데서도 소중한 이의 소리를 알아듣고 그 곁에 나란히 서요. | J7: 시간과 책임을 맡는 토성이 다섯 행성 중 가장 많은 긴장을 받고 있어요. 그래서 관계가 단단하다고 믿는 일에 가장 큰 에너지가 듭니다. 그럴 때 상대에게 맞춰 무리의 온기를 지키려는 것은, 차트에서 물의 기운이 가장 강하기 때문이에요. | K7: 함께하는 이들의 마음을 살펴 모두가 따뜻할 수 있도록 자리를 지키는 힘이 있습니다. | L7: 관계가 흔들릴까 봐 서운한 마음까지 꾹 참고 맞춰 주는 순간이에요. | M7: 오늘 하나쯤은 내가 원하는 것을 먼저 말하고 관계가 어떤지 지켜봐 주세요. | N7: 추운 날 곁을 내어 주는 펭귄, 정말 따뜻해요 | O7: 관계성 테스트 base_knowledge 원문과 대조 필요 | P7: 미검수
A8: CHAR_07_HERON | B8: 왜가리 | C8: 믿기 | D8: 거리두기 | E8: 토성 | F8: 공기 | G8: character-07-heron.png | H8: 관계를 믿고 마음을 놓는 일에 에너지가 많이 들고, 그럴 때 한발 물러나 혼자 정리하는 유형 | I8: 왜가리는 얕은 물가에 오래 서서 물결을 지켜본 뒤에야 한 걸음 내딛는 캐릭터예요. 서두르지 않고 멀리서 바라보며 믿어도 될지 스스로 가늠합니다. | J8: 책임과 시험의 별 토성이 다섯 행성 가운데 가장 많은 긴장을 받고 있습니다. 그래서 관계를 믿고 마음을 맡기는 일이 가장 에너지가 드는 역량이 돼요. 그럴 때 가까이 붙기보다 한발 떨어져 생각으로 상황을 살피는 것은, 차트에서 공기의 기운이 가장 강하기 때문입니다. | K8: 감정에 휩쓸리지 않고 사람과 상황을 차분하게 지켜보는 눈이 있어요. | L8: 다가오는 마음을 반기면서도 정말 믿어도 될지 혼자 오래 따져 보는 순간입니다. | M8: 지켜본 것 가운데 이미 믿을 만했던 순간을 하나 골라 고맙다고 전해 보세요. | N8: 오래 지켜본 만큼 깊이 믿는 왜가리예요 | O8: 관계성 테스트 base_knowledge 원문과 대조 필요 | P8: 미검수
A9: CHAR_08_SWAN | B9: 백조 | C9: 믿기 | D9: 조율하기 | E9: 토성 | F9: 흙 | G9: character-08-swan.png | H9: 관계를 믿고 마음을 놓는 일에 에너지가 많이 들고, 그럴 때 현실적으로 따져 조율하는 유형 | I9: 백조는 물 위에서는 우아하게 떠 있지만 물 아래에서는 쉬지 않고 발을 젓는 캐릭터입니다. 겉으로는 고요해 보여도 관계가 흔들리지 않도록 속에서 차근차근 균형을 잡아요. | J9: 구조와 약속을 맡는 토성이 다섯 행성 가운데 가장 많은 긴장을 받고 있어요. 그래서 관계를 믿고 마음을 놓는 일에 가장 큰 에너지가 듭니다. 그럴 때 약속과 생활의 틀을 현실적으로 맞춰 가며 안심을 찾는 것은, 차트에서 흙의 기운이 가장 강하기 때문이에요. | K9: 약속을 지키고 일상을 꾸준히 이어 가며 믿을 만한 관계를 쌓는 힘이 있습니다. | L9: 겉으로는 평온한 척하며 물 아래에서 혼자 계획을 다시 짜는 순간이에요. | M9: 물 아래에서 젓던 발을 잠시 멈추고, 지금 불안한 점 하나를 말로 꺼내 보세요. | N9: 고요한 물 위의 백조, 속으로 늘 애쓰고 있어요 | O9: 관계성 테스트 base_knowledge 원문과 대조 필요 (모의실험상 가장 드문 캐릭터 — 설명 분량 다른 행과 균형 확인) | P9: 미검수
A10: CHAR_09_PUFFERFISH | B10: 복어 | C10: 선 지키기 | D10: 다가가기 | E10: 화성 | F10: 불 | G10: character-09-pufferfish.png | H10: 내 선을 지키는 일에 에너지가 많이 들고, 그럴 때 먼저 다가가는 유형 | I10: 복어는 누가 내 선을 넘어온다 싶으면 몸을 크게 부풀려 바로 신호를 보내는 캐릭터예요. 평소엔 동글동글 순하지만 지킬 것 앞에서는 망설이지 않습니다. | J10: 의욕과 행동을 맡는 화성이 다섯 행성 가운데 가장 많은 긴장을 받고 있습니다. 그래서 나의 선을 세우고 지키는 일이 가장 에너지가 드는 역량이에요. 그럴 때 참고 넘기기보다 바로 표현해 선을 그으려는 것은, 차트에서 불의 기운이 가장 강하기 때문입니다. | K10: 불편한 것을 오래 묵히지 않고 솔직하게 알려 관계를 투명하게 만드는 힘이 있어요. | L10: 마음보다 몸이 먼저 부풀어 올라 말이 생각보다 세게 나가는 순간입니다. | M10: 몸이 부풀어 오를 때 숨을 길게 내쉬고, 원하는 것 하나만 골라 말해 보세요. | N10: 솔직하게 부풀 줄 아는 복어, 그 용기 멋져요 | O10: 관계성 테스트 base_knowledge 원문과 대조 필요 (복어의 독 이미지는 일부러 쓰지 않았음) | P10: 미검수
A11: CHAR_10_HERMIT_CRAB | B11: 소라게 | C11: 선 지키기 | D11: 맞춰주기 | E11: 화성 | F11: 물 | G11: character-10-hermit-crab.png | H11: 내 선을 지키는 일에 에너지가 많이 들고, 그럴 때 상대에게 맞춰 주는 유형 | I11: 소라게는 주변 친구들과 차례를 맞춰 껍데기를 바꿔 입는 캐릭터입니다. 모두가 편하도록 자리를 내주다 보면 정작 내게 맞는 집을 놓치기도 해요. | J11: 나를 지키는 힘을 맡는 화성이 다섯 행성 중 가장 많은 긴장을 받고 있어요. 그래서 여기까지라고 선을 긋는 일에 가장 큰 에너지가 듭니다. 그럴 때 거절하기보다 상대 기분에 맞춰 내 자리를 조금씩 내어 주는 것은, 차트에서 물의 기운이 가장 강하기 때문이에요. | K11: 상대의 사정을 헤아려 부드럽게 양보하며 관계의 평화를 지키는 힘이 있습니다. | L11: 싫다는 말이 목까지 왔는데 상대 표정을 보고 다시 삼키는 순간이에요. | M11: 이번 주에는 작은 부탁 하나쯤 ‘이번엔 어려워요’라고 다정하게 거절해 보세요. | N11: 내게 꼭 맞는 껍데기도 챙기는 소라게가 되길 | O11: 관계성 테스트 base_knowledge 원문과 대조 필요 (모의실험상 가장 흔한 캐릭터 — 공유 문구 반응 확인) | P11: 미검수
A12: CHAR_11_TURTLE | B12: 거북 | C12: 선 지키기 | D12: 거리두기 | E12: 화성 | F12: 공기 | G12: character-11-turtle.png | H12: 내 선을 지키는 일에 에너지가 많이 들고, 그럴 때 한발 물러나 혼자 정리하는 유형 | I12: 거북은 마음이 침범당한다고 느끼면 조용히 등딱지 안으로 들어가 숨을 고르는 캐릭터예요. 충분히 쉰 뒤에야 다시 고개를 내밀고 천천히 길을 이어 갑니다. | J12: 행동과 자기주장을 맡는 화성이 다섯 행성 가운데 가장 많은 긴장을 받고 있습니다. 그래서 나의 선을 말로 세우는 일이 가장 에너지가 드는 역량이 돼요. 그럴 때 맞서기보다 잠시 물러나 혼자 생각을 정리하는 것은, 차트에서 공기의 기운이 가장 강하기 때문입니다. | K12: 부딪힐 때도 감정적으로 맞서지 않고 차분하게 나를 지키는 힘이 있어요. | L12: 불편하다는 말 대신 등딱지 안에서 혼자 오래 머무는 순간입니다. | M12: 등딱지 안에 들어갈 때 조금 쉬고 다시 이야기하겠다고 한마디 남겨 보세요. | N12: 쉬었다 다시 걷는 거북, 그 속도도 괜찮아요 | O12: 관계성 테스트 base_knowledge 원문과 대조 필요 | P12: 미검수
A13: CHAR_12_CLAM | B13: 조개 | C13: 선 지키기 | D13: 조율하기 | E13: 화성 | F13: 흙 | G13: character-12-clam.png | H13: 내 선을 지키는 일에 에너지가 많이 들고, 그럴 때 현실적으로 따져 조율하는 유형 | I13: 조개는 물이 맑을 때만 껍데기를 살짝 열고, 흐려지면 단단히 닫는 캐릭터입니다. 얼마나 열지 상황을 보며 하나하나 가늠하는 신중한 문지기예요. | J13: 나를 지키는 추진력의 별 화성이 다섯 행성 가운데 가장 많은 긴장을 받고 있어요. 그래서 내 경계를 세우고 지키는 일에 가장 큰 에너지가 듭니다. 그럴 때 감정보다 조건과 사정을 따져 어디까지 열지 조정하는 것은 차트에서 흙의 기운이 가장 강하기 때문이에요. | K13: 무엇을 받아들이고 무엇을 거를지 현실적으로 가려내는 힘이 있습니다. | L13: 열어야 할지 닫아야 할지 계산하느라 내 마음을 들여다볼 틈이 없는 순간이에요. | M13: 따져 보기 전에 지금 내 마음이 열고 싶은지부터 물어봐 주세요. | N13: 천천히 열리는 조개, 그 안은 참 부드러워요 | O13: 관계성 테스트 base_knowledge 원문과 대조 필요 | P13: 미검수
... A21: CHAR_20_STARFISH | B21: 불가사리 | C21: 회복하기 | D21: 조율하기 | E21: 금성 | F21: 흙 | G21: character-20-starfish.png | H21: 다툰 뒤 다시 가까워지는 일에 에너지가 많이 들고, 그럴 때 현실적으로 따져 조율하는 유형 | I21: 불가사리는 상처 난 팔도 시간을 들여 천천히 다시 길러 내는 캐릭터입니다. 서두르지 않고 작은 발을 하나씩 움직여 어긋났던 자리로 다시 다가가요. | J21: 관계와 조화를 맡는 금성이 다섯 행성 중 가장 많은 긴장을 받고 있어요. 그래서 다툰 뒤 관계를 회복하는 일에 가장 큰 에너지가 듭니다. 그럴 때 무엇이 어긋났는지 현실적으로 따져 하나씩 맞춰 가는 것은, 차트에서 흙의 기운이 가장 강하기 때문이에요. | K21: 다툼의 원인을 차근차근 짚어 같은 일이 덜 반복되도록 다듬는 힘이 있습니다. | L21: 상대는 마음을 알아주길 바라는데 해결책부터 정리하고 있는 순간이에요. | M21: 해결책을 꺼내기 전에 그때 많이 속상했겠다는 한마디를 먼저 건네 보세요. | N21: 천천히 다시 자라는 불가사리, 그 끈기를 응원해요 | O21: 관계성 테스트 base_knowledge 원문과 대조 필요 | P21: 미검수

Sheet A6 역량 5 · 방식 4 설명
A1: ID | B1: 구분(역량/방식) | C1: 이름 | D1: 대응 행성·원소 | E1: 쉬운 정의 | F1: 점성술 연결 설명 | G1: 흔들릴 때 / 방식의 힘과 지나칠 때 | H1: 검수 메모 | I1: 검수상태 | J1: 수정 문장 | K1: 상담사 메모
A2: COMP_LEAN | B2: 역량 | C2: 기대기 | D2: 달 | E2: 기대기는 가까운 사람에게 마음을 기대고 위로를 주고받는 친밀감의 역량입니다. | F2: 달은 차트에서 감정과 마음의 안정을 맡는 별이에요. 달이 긴장하는 각도를 많이 받으면 편히 기대고 싶은 마음과 혼자 버티려는 마음이 자주 부딪힙니다. 그래서 달은 누군가에게 기대는 힘을 비춰 보는 자리로 읽어요. | G2: 힘든 일이 있어도 괜찮은 척 넘기거나, 반대로 연락 하나에 마음이 크게 출렁이기 쉬워요. 기대고 싶은 마음과 짐이 될까 하는 걱정이 함께 올라오는 때입니다. | H2: 관계성 테스트 초기 기획에는 친밀감 역량 이름이 '다가가기'로 적힌 기록이 있음 — 방식 '다가가기'와 겹치지 않도록 최종 명칭(기대기) 확인 필요 | I2: 미검수
A3: COMP_TRUST | B3: 역량 | C3: 믿기 | D3: 토성 | E3: 믿기는 관계가 쉽게 흔들리지 않으리라 여기고 마음을 놓는 안정감의 역량이에요. | F3: 토성은 책임과 구조, 시간을 견디는 힘을 맡는 별입니다. 토성이 긴장하는 각도를 많이 받으면 관계에서도 이 사이가 단단한지 자꾸 점검하고 싶어져요. 그래서 토성은 시간을 두고 쌓이는 믿음을 비춰 보는 자리로 읽습니다. | G3: 답장이 늦거나 말투가 조금만 달라져도 관계 전체가 흔들리는 듯 느끼기 쉽습니다. 확인을 받아도 마음이 오래 놓이지 않아 스스로 지치기도 해요. | I3: 미검수
A4: COMP_BOUNDARY | B4: 역량 | C4: 선 지키기 | D4: 화성 | E4: 선 지키기는 내가 편한 범위와 원하지 않는 것을 알고 지켜 내는 경계의 역량입니다. | F4: 화성은 의욕과 행동, 나를 지키려는 추진력을 맡는 별이에요. 화성이 긴장하는 각도를 많이 받으면 싫다는 마음을 언제 어떻게 꺼낼지 고르는 데 힘이 많이 듭니다. 그래서 화성은 나의 선을 세우고 지키는 힘을 비춰 보는 자리로 읽어요. | G4: 부탁을 거절하지 못해 일을 떠안거나, 참다가 한꺼번에 날카롭게 터지기 쉬워요. 어디까지가 내 몫인지 헷갈려 한참 지나서야 지친 마음을 알아차리기도 합니다. | H4: 화성 = 경계 연결은 '자기주장·나를 지키는 힘' 상징으로 풀었음 — 공격성으로 읽히지 않는지 확인 | I4: 미검수
A5: COMP_SPEAK | B5: 역량 | C5: 말하기 | D5: 수성 | E5: 말하기는 내 생각과 마음을 상대가 알아들을 수 있는 말로 꺼내는 표현의 역량이에요. | F5: 수성은 생각과 말, 연락을 맡는 별입니다. 수성이 긴장하는 각도를 많이 받으면 머릿속 생각은 많은데 입 밖으로 꺼내는 순간에 힘이 많이 들어요. 그래서 수성은 마음을 말로 옮기는 힘을 비춰 보는 자리로 읽습니다. | G5: 하고 싶은 말을 여러 번 고쳐 쓰다 결국 보내지 못하거나, 말해 놓고 오래 곱씹기 쉽습니다. 내 뜻이 다르게 전해질까 봐 꼭 필요한 말까지 삼키기도 해요. | I5: 미검수
A6: COMP_REPAIR | B6: 역량 | C6: 회복하기 | D6: 금성 | E6: 회복하기는 다툼이나 서운함이 생긴 뒤 관계를 다시 따뜻하게 잇는 갈등 회복의 역량입니다. | F6: 금성은 좋아하는 것과 관계, 조화를 맡는 별이에요. 금성이 긴장하는 각도를 많이 받으면 어긋난 사이를 다시 부드럽게 맞추는 데 마음이 많이 쓰입니다. 그래서 금성은 틈이 생긴 관계를 다시 잇는 힘을 비춰 보는 자리로 읽어요. | G6: 작은 말다툼 뒤에도 분위기가 풀리지 않을까 봐 오래 마음이 무거워지기 쉬워요. 먼저 사과할지 기다릴지 고민하다 화해의 때를 놓치기도 합니다. | I6: 미검수
A7: STYLE_APPROACH | B7: 방식 | C7: 다가가기 | D7: 불 | E7: 다가가기는 마음이 흔들릴 때 기다리기보다 먼저 연락하고 움직여 거리를 좁히는 방식입니다. | F7: 불의 원소는 양자리·사자자리·사수자리의 기운으로, 열정과 시작하는 힘을 상징해요. 불이 강한 차트는 마음이 움직이면 몸도 먼저 움직이려는 결로 읽습니다. 그래서 흔들릴 때 먼저 다가가는 방식과 이어져요. | G7: 어색한 공기를 오래 두지 않고 먼저 손을 내밀어, 관계가 식지 않게 지켜 준 방법이에요. 다만 지나치면 상대가 준비되기 전에 답을 재촉하게 되어 내 마음이 더 급해질 수 있습니다. | I7: 미검수
A8: STYLE_ATTUNE | B8: 방식 | C8: 맞춰주기 | D8: 물 | E8: 맞춰주기는 마음이 흔들릴 때 상대의 기분과 분위기에 나를 맞춰 관계의 평화를 지키는 방식이에요. | F8: 물의 원소는 게자리·전갈자리·물고기자리의 기운으로, 감정을 느끼고 스며드는 힘을 상징합니다. 물이 강한 차트는 말보다 분위기를 먼저 살피는 결로 읽어요. 그래서 흔들릴 때 상대에게 맞춰 주는 방식과 이어집니다. | G8: 상대의 마음을 먼저 알아채고 품어 주어, 부딪힘 없이 곁을 지켜 준 방법입니다. 다만 지나치면 내 기분을 자꾸 뒤로 미뤄 두다 나도 모르게 서운함이 쌓일 수 있어요. | I8: 미검수
A9: STYLE_DISTANCE | B9: 방식 | C9: 거리두기 | D9: 공기 | E9: 거리두기는 마음이 흔들릴 때 잠시 한 걸음 물러나 혼자 생각을 정리할 시간을 갖는 방식입니다. | F9: 공기의 원소는 쌍둥이자리·천칭자리·물병자리의 기운으로, 생각하고 한발 떨어져 바라보는 힘을 상징해요. 공기가 강한 차트는 감정이 차오를 때 머리로 먼저 정리하려는 결로 읽습니다. 그래서 흔들릴 때 거리를 두고 숨을 고르는 방식과 이어져요. | G9: 감정이 앞설 때 한발 물러나, 후회할 말 대신 차분한 생각을 고르게 해 준 방법이에요. 다만 지나치면 상대에게 닫힌 문처럼 느껴져 마음의 거리가 벌어질 수 있습니다. | H9: '거리두기'가 회피 성향 꼬리표처럼 읽히지 않도록 '혼자 정리할 시간' 중심으로 썼음 — 관계성 테스트 방식 정의 문구와 대조 필요 | I9: 미검수
A10: STYLE_COORDINATE | B10: 방식 | C10: 조율하기 | D10: 흙 | E10: 조율하기는 마음이 흔들릴 때 무엇이 가능한지 현실적으로 따져 보고 조정점을 찾는 방식이에요. | F10: 흙의 원소는 황소자리·처녀자리·염소자리의 기운으로, 현실을 다지고 지키는 힘을 상징합니다. 흙이 강한 차트는 마음보다 눈앞의 해결책을 먼저 찾으려는 결로 읽어요. 그래서 흔들릴 때 차근차근 따지고 맞춰 가는 방식과 이어집니다. | G10: 감정에 휩쓸리지 않고 할 수 있는 일부터 정리해, 관계를 현실의 땅 위에 붙잡아 준 방법입니다. 다만 지나치면 마음을 듣기보다 해결책부터 내밀어 상대가 서운해할 수 있어요. | I10: 미검수

Sheet A7 원소 강할 때·부족할 때
A1: ID | B1: 원소 | C1: 상태 | D1: 본문 | E1: 캐릭터 방식 연결 | F1: 검수 메모 | G1: 검수상태 | H1: 수정 문장 | I1: 상담사 메모
A2: ELEM_FIRE_STRONG | B2: 불 | C2: 강할 때 | D2: 불의 기운이 강하면 마음먹은 순간 바로 움직이는 추진력과 열정이 돋보입니다. 새로운 시작 앞에서 설레고, 그 에너지가 주변 사람까지 움직이게 해요. 다만 불이 셀수록 쉬는 타이밍을 의식적으로 정해 두는 편이 좋습니다. | E2: 불이 가장 강하면, 마음이 흔들릴 때 먼저 움직여 다가가는 ‘다가가기’ 방식을 쓰기 쉬워요. | F2: 강할 때·부족할 때의 점수 경계는 엔진에서 정합니다. style_link는 그 원소가 차트에서 가장 강할 때만 노출된다는 전제로 썼습니다. | G2: 미검수
A3: ELEM_FIRE_WEAK | B3: 불 | C3: 부족할 때 | D3: 불의 기운이 적은 차트는 즉흥적인 추진력 대신 꾸준함이나 생각, 공감으로 일을 이끌어 온 경우가 많아요. 그렇게 쌓아 온 방식이 이미 나만의 힘입니다. 하고 싶은 일을 미뤄 두고 있다면, 작게라도 오늘 시작해 보는 연습을 의식적으로 챙겨 보세요. | G3: 미검수
A4: ELEM_EARTH_STRONG | B4: 흙 | C4: 강할 때 | D4: 흙의 기운이 강하면 현실 감각이 뛰어나고, 눈에 보이는 결과를 차근차근 쌓아 가는 힘이 있습니다. 계획을 세우고 끝까지 지켜 내는 성실함이 주변에 믿음을 줘요. 다만 확인할 것이 많아질수록 즉흥적인 즐거움이 줄어들 수 있습니다. | E4: 흙이 가장 강하면, 마음이 흔들릴 때 현실적으로 따지고 조정하는 ‘조율하기’ 방식을 쓰기 쉬워요. | G4: 미검수
A5: ELEM_EARTH_WEAK | B5: 흙 | C5: 부족할 때 | D5: 흙의 기운이 적은 차트는 정해진 틀보다 열정이나 아이디어, 감정의 흐름을 따라 움직여 온 경우가 많아요. 그 유연함 덕분에 새로운 상황에도 빠르게 적응할 수 있습니다. 잠, 식사, 정리 같은 생활 루틴을 의식적으로 챙기면 생각과 마음이 한결 안정돼요. | G5: 미검수
A6: ELEM_AIR_STRONG | B6: 공기 | C6: 강할 때 | D6: 공기의 기운이 강하면 생각이 빠르고, 상황을 한 걸음 떨어져서 바라보는 힘이 있습니다. 대화와 정보를 통해 사람과 아이디어를 잇는 데 능숙해요. 다만 머리로 이해하는 데서 멈추면 정작 내 감정은 놓치기 쉽습니다. | E6: 공기가 가장 강하면, 마음이 흔들릴 때 혼자 정리할 시간을 갖는 ‘거리두기’ 방식을 쓰기 쉬워요. | G6: 미검수
A7: ELEM_AIR_WEAK | B7: 공기 | C7: 부족할 때 | D7: 공기의 기운이 적은 차트는 말로 풀어내기보다 행동이나 감각, 마음으로 먼저 반응해 온 경우가 많아요. 그만큼 직접 겪으며 얻은 판단에 깊이가 있습니다. 감정이 클 때 한 걸음 물러나 생각을 적어 보거나 다른 사람의 관점을 들어 보는 시간을 챙겨 보세요. | F7: 샘플 리포트처럼 원소 점수가 영점인 차트도 이 부족할 때 문장을 그대로 씁니다. 영점일 때 별도 문장이 필요한지 확인 부탁드립니다. | G7: 미검수
A8: ELEM_WATER_STRONG | B8: 물 | C8: 강할 때 | D8: 물의 기운이 강하면 다른 사람의 마음을 섬세하게 읽고 깊이 공감하는 힘이 있습니다. 말하지 않아도 분위기를 알아채고 먼저 품어 주는 따뜻함이 있어요. 다만 남의 감정까지 함께 짊어지면 금방 지칠 수 있어, 혼자 비워 내는 시간이 필요합니다. | E8: 물이 가장 강하면, 마음이 흔들릴 때 상대에게 맞춰 분위기를 지키는 ‘맞춰주기’ 방식을 쓰기 쉬워요. | G8: 미검수
A9: ELEM_WATER_WEAK | B9: 물 | C9: 부족할 때 | D9: 물의 기운이 적은 차트는 감정에 머물기보다 행동이나 생각, 현실 감각으로 상황을 헤쳐 온 경우가 많아요. 덕분에 어려운 순간에도 침착하게 중심을 잡을 수 있습니다. 가끔은 ‘지금 내 기분은 어떤가’를 스스로 묻고, 그 마음을 믿을 만한 사람에게 꺼내 보는 시간을 챙겨 보세요. | G9: 미검수

Sheet A8 트랜짓 이벤트 문장
A1: ID | B1: 트랜짓 행성 | C1: 출생 대상 | D1: 각도 묶음 | E1: 이벤트 이름 | F1: 그 뜻 한 줄 | G1: 표 문장(과거) | H1: 표 문장(미래) | I1: 본문(2~3문장) | J1: 톤 | K1: 키워드 | L1: 검수 메모 | M1: 검수상태 | N1: 수정 문장 | O1: 상담사 메모
A2: TR_JUPITER_SUN_CONJ | B2: 목성 | C2: 태양 | D2: 합 | E2: 목성-태양 합 | F2: 확장의 별이 나의 중심에 겹치는 자리 — 나를 넓게 펼치고 싶은 마음이 커져요 | G2: 나를 드러낼 기회가 늘고, 자신감이 한 뼘 자랐을 거예요. | H2: 나다운 일을 더 크게 펼쳐 보기 좋은 때입니다. | I2: 확장의 별이 나의 중심에 겹치는 시기입니다. 스스로를 믿는 힘이 커져서, 미뤄 둔 도전에 손을 뻗기 쉬워요. 일에서든 일상에서든 ‘해 보자’는 말이 자주 나오는 때일 수 있습니다. | J2: 순풍 | K2: 나를 펼치기 | M2: 미검수
A3: TR_JUPITER_SUN_HARM | B3: 목성 | C3: 태양 | D3: 조화 | E3: 목성-태양 조화 | F3: 확장의 별이 나의 중심을 자연스럽게 돕는 각도 — 애쓰지 않아도 일이 풀리는 느낌을 줘요 | G3: 크게 애쓰지 않았는데도 일이 술술 풀린 순간이 있었을 거예요. | H3: 자연스럽게 들어오는 기회에 가볍게 응해 보기 좋은 때예요. | I3: 확장의 별이 나의 중심을 자연스럽게 돕는 각도에 있습니다. 내 모습 그대로 있을 때 도움과 기회가 따라오기 쉬워요. 주변의 제안이나 소개에 한 번 더 귀 기울여 볼 만한 시기입니다. | J3: 순풍 | K3: 순한 기회 | M3: 미검수
A4: TR_JUPITER_SUN_TENSE | B4: 목성 | C4: 태양 | D4: 긴장 | E4: 목성-태양 긴장 | F4: 확장의 별이 나의 중심과 부딪치는 각도 — 의욕이 커지는 만큼 과신하기 쉬워요 | G4: 하고 싶은 일이 많아져 계획보다 크게 벌인 일이 있었을 수 있어요. | H4: 벌이고 싶은 일 가운데 정말 원하는 것만 고르기 좋은 때입니다. | I4: 확장의 별이 나의 중심과 긴장하는 각도를 이룹니다. 자신감과 의욕이 커지는 건 좋은 신호지만, 감당할 수 있는 크기보다 크게 약속하기 쉬워요. 시작하기 전에 ‘이걸 끝까지 해낼 수 있을까’를 한 번 물어보는 것으로 충분합니다. | J4: 중립 | K4: 알맞은 크기 | L4: 목성 긴장은 과함·과신 주의로 '중립' 처리 | M4: 미검수
A5: TR_JUPITER_MOON_CONJ | B5: 목성 | C5: 달 | D5: 합 | E5: 목성-달 합 | F5: 확장의 별이 감정의 별과 겹치는 자리 — 마음의 품이 넓어지고 집이 편안해져요 | G5: 마음이 한결 넉넉해지고, 집이나 가까운 사람 곁에서 위로를 받았을 거예요. | H5: 집과 마음의 자리를 넉넉하게 가꾸기 좋은 때예요. | I5: 확장의 별이 감정의 별과 겹치는 시기예요. 마음의 품이 넓어져 나와 주변을 너그럽게 바라보기 쉽습니다. 머무는 공간을 정돈하거나 가까운 사람과 저녁을 나누는 일이 오래 힘이 될 수 있어요. | J5: 순풍 | K5: 마음의 품 | M5: 미검수
A6: TR_JUPITER_MOON_HARM | B6: 목성 | C6: 달 | D6: 조화 | E6: 목성-달 조화 | F6: 확장의 별이 감정의 별을 자연스럽게 돕는 각도 — 마음이 편안하게 차오르게 해요 | G6: 기분이 안정되고, 작은 일상에서 기쁨을 자주 느꼈을 수 있습니다. | H6: 마음이 편해지는 습관을 하나 들여 보기 좋은 때입니다. | I6: 확장의 별이 감정의 별을 자연스럽게 돕는 각도에 있어요. 큰일이 없어도 마음이 차분히 채워지고, 누군가에게 기대는 일도 덜 어렵게 느껴질 수 있습니다. 이 편안함을 작은 루틴으로 붙잡아 두면 바쁜 시기에 돌아올 자리가 돼요. | J6: 순풍 | K6: 편안한 마음 | M6: 미검수
A7: TR_JUPITER_MOON_TENSE | B7: 목성 | C7: 달 | D7: 긴장 | E7: 목성-달 긴장 | F7: 확장의 별이 감정의 별과 긴장하는 각도 — 기쁨도 서운함도 크게 부풀기 쉬워요 | G7: 기분이 크게 오르내리거나, 마음 가는 대로 약속을 늘린 때가 있었을 거예요. | H7: 감정이 클 때는 결정을 하루 묵혀 두기 좋은 때예요. | I7: 확장의 별이 감정의 별과 긴장하는 각도를 이룹니다. 좋은 기분도 서운함도 평소보다 크게 느껴져, 기분에 따라 지출이나 약속을 늘리기 쉬워요. 마음이 커질 때 바로 움직이기보다 하루쯤 지켜보는 여유를 두면 좋습니다. | J7: 중립 | K7: 마음 고르기 | L7: 목성 긴장은 과함·과신 주의로 '중립' 처리 | M7: 미검수
A8: TR_JUPITER_MERCURY_CONJ | B8: 목성 | C8: 수성 | D8: 합 | E8: 목성-수성 합 | F8: 확장의 별이 생각·말의 별과 겹치는 자리 — 배우고 말하고 싶은 것이 많아져요 | G8: 새로운 배움이나 대화가 늘고, 아이디어가 많이 떠올랐을 거예요. | H8: 배우고 쓰고 말하는 일에 시간을 내기 좋은 때입니다. | I8: 확장의 별이 생각과 말의 별에 겹치는 시기입니다. 호기심이 커지고, 내 생각을 말이나 글로 꺼내기가 한결 쉬워져요. 미뤄 둔 공부나 기록, 오래 하지 못한 대화를 시작해 보기 좋은 때예요. | J8: 순풍 | K8: 배움과 말 | M8: 미검수
A9: TR_JUPITER_MERCURY_HARM | B9: 목성 | C9: 수성 | D9: 조화 | E9: 목성-수성 조화 | F9: 확장의 별이 생각·말의 별을 자연스럽게 돕는 각도 — 말과 연락이 잘 통하게 해요 | G9: 연락이 잘 닿고, 말이 통하는 사람을 만나 일이 수월했을 수 있어요. | H9: 제안하고 연락하고 생각을 정리해 말하기 좋은 때예요. | I9: 확장의 별이 생각과 말의 별을 자연스럽게 돕는 각도에 있습니다. 설명이 잘 전달되고, 필요한 정보나 사람과 연결되기 쉬워요. 미뤄 둔 제안이나 연락을 이때 보내 보는 것도 방법입니다. | J9: 순풍 | K9: 통하는 말 | M9: 미검수
A10: TR_JUPITER_MERCURY_TENSE | B10: 목성 | C10: 수성 | D10: 긴장 | E10: 목성-수성 긴장 | F10: 확장의 별이 생각·말의 별과 긴장하는 각도 — 말과 약속이 앞서가기 쉬워요 | G10: 생각이 많아지거나, 지키기 빠듯한 약속을 한 적이 있었을 거예요. | H10: 말하기 전에 한 번 더 정리하고, 약속은 줄여 잡기 좋은 때입니다. | I10: 확장의 별이 생각과 말을 맡은 별과 긴장하는 각도를 이룹니다. 아이디어는 풍성하지만 세부를 건너뛰거나, 할 수 있는 것보다 크게 말하기 쉬워요. 계약서나 일정은 조건을 한 번 더 읽어 보는 습관이 도움이 됩니다. | J10: 중립 | K10: 세부 챙기기 | L10: 목성 긴장은 과함·과신 주의로 '중립' 처리 | M10: 미검수
A11: TR_JUPITER_VENUS_CONJ | B11: 목성 | C11: 금성 | D11: 합 | E11: 목성-금성 합 | F11: 확장의 별이 좋아하는 것·관계의 별과 겹치는 자리 — 즐거움과 다정함이 커져요 | G11: 좋아하는 것을 즐길 일이 많고, 사람들과의 관계가 한결 따뜻했을 거예요. | H11: 좋아하는 것을 마음껏 즐기고 고마운 사람을 챙기기 좋은 때예요. | I11: 확장의 별이 좋아하는 것과 관계를 맡은 별에 겹치는 시기예요. 아름다운 것, 즐거운 자리, 다정한 사람에게 마음이 열리기 쉽습니다. 즐거움을 아끼지 않되, 기분 좋을 때 커지는 씀씀이는 한 번쯤 돌아봐도 좋아요. | J11: 순풍 | K11: 즐거움 | M11: 미검수
A12: TR_JUPITER_VENUS_HARM | B12: 목성 | C12: 금성 | D12: 조화 | E12: 목성-금성 조화 | F12: 확장의 별이 좋아하는 것·관계의 별을 자연스럽게 돕는 각도 — 관계에 온기가 돌아요 | G12: 사람들과 어울리는 자리가 편안하고, 소소한 행운이 따랐을 수 있습니다. | H12: 관계에 온기를 더하고, 나를 위한 작은 선물을 해 보기 좋은 때입니다. | I12: 확장의 별이 좋아하는 것과 관계를 맡은 별을 자연스럽게 돕는 각도에 있습니다. 호감이 잘 전해지고, 함께하는 자리가 부드럽게 흘러가기 쉬워요. 고마웠던 사람에게 먼저 안부를 건네기 좋은 흐름이에요. | J12: 순풍 | K12: 관계의 온기 | M12: 미검수
A13: TR_JUPITER_VENUS_TENSE | B13: 목성 | C13: 금성 | D13: 긴장 | E13: 목성-금성 긴장 | F13: 확장의 별이 즐거움·돈의 감각과 부딪치는 각도 — 기분에 들떠 지나치기 쉬워요 | G13: 즐거운 만큼 지출이나 약속이 늘어, 나중에 조금 버거웠을 수 있어요. | H13: 즐거움은 지키되 지출과 약속의 선을 정해 두기 좋은 때예요. | I13: 확장의 별이 즐거움과 돈의 감각을 맡은 별과 긴장하는 각도를 이룹니다. 좋은 기분이 커지면서 사고 싶은 것, 하고 싶은 것이 한꺼번에 늘기 쉬워요. 즐거움을 줄이기보다 미리 정한 선 안에서 누리면 뒤탈 없이 즐거움만 남습니다. | J13: 중립 | K13: 즐거움의 선 | L13: 목성 긴장은 과함·과신 주의로 '중립' 처리 | M13: 미검수
A14: TR_JUPITER_MARS_CONJ | B14: 목성 | C14: 화성 | D14: 합 | E14: 목성-화성 합 | F14: 확장의 별이 의욕의 별과 겹치는 자리 — 움직일 힘과 용기가 커져요 | G14: 의욕이 솟아 새 일을 벌이거나 오래 미룬 일을 밀어붙였을 거예요. | H14: 미뤄 둔 도전을 실제로 시작해 보기 좋은 때입니다. | I14: 확장의 별이 의욕과 행동의 별에 겹치는 시기입니다. 마음이 앞으로 나가려 해서, 생각만 하던 일을 실행에 옮기기 쉬워요. 이 힘을 한두 가지 목표에 모으면 결과로 남기 좋습니다. | J14: 순풍 | K14: 실행력 | M14: 미검수
A15: TR_JUPITER_MARS_HARM | B15: 목성 | C15: 화성 | D15: 조화 | E15: 목성-화성 조화 | F15: 확장의 별이 의욕의 별을 자연스럽게 돕는 각도 — 노력이 결과로 이어지기 쉬워요 | G15: 애쓴 만큼 성과가 보이고, 꾸준히 밀고 나갈 힘이 있었을 거예요. | H15: 꾸준히 해 온 일에 속도를 조금 더 붙여 보기 좋은 때예요. | I15: 확장의 별이 의욕의 별을 자연스럽게 돕는 각도에 있어요. 움직인 만큼 반응이 오니, 하던 일에 탄력이 붙기 쉽습니다. 산책이나 운동처럼 몸을 쓰는 루틴을 새로 들이기에도 좋은 흐름이에요. | J15: 순풍 | K15: 탄력 | M15: 미검수
A16: TR_JUPITER_MARS_TENSE | B16: 목성 | C16: 화성 | D16: 긴장 | E16: 목성-화성 긴장 | F16: 확장의 별이 의욕의 별과 긴장하는 각도 — 의욕이 앞서 무리하기 쉬워요 | G16: 의욕이 넘쳐 무리하거나, 성급하게 부딪친 순간이 있었을 수 있어요. | H16: 힘을 쓸 곳과 아낄 곳을 나눠 보기 좋은 때입니다. | I16: 확장의 별이 의욕의 별과 긴장하는 각도를 이룹니다. 힘이 넘치는 만큼 한꺼번에 많은 일을 붙잡거나, 답답한 상황에 크게 맞서기 쉬워요. 하루의 끝에 쉬는 시간을 먼저 정해 두면 그 힘을 오래 쓸 수 있습니다. | J16: 중립 | K16: 힘 조절 | L16: 목성 긴장은 과함·과신 주의로 '중립' 처리 | M16: 미검수
A17: TR_JUPITER_ASC_CONJ | B17: 목성 | C17: 상승궁 | D17: 합 | E17: 목성-상승궁 합 | F17: 확장의 별이 나를 드러내는 자리에 겹치는 때 — 나를 보여 줄 무대가 넓어져요 | G17: 사람들 앞에 설 일이 늘고, 나를 보는 시선이 달라졌을 거예요. | H17: 새로운 모습으로 나를 소개해 보기 좋은 때입니다. | I17: 확장의 별이 나를 드러내는 자리에 겹치는 시기입니다. 표정과 태도에 여유가 생겨, 처음 만나는 사람에게도 좋은 인상을 남기기 쉬워요. 새 모임이나 새 역할에서 나의 다른 면을 보여 줄 수 있는 때예요. | J17: 순풍 | K17: 새 무대 | M17: 미검수
A18: TR_JUPITER_ASC_HARM | B18: 목성 | C18: 상승궁 | D18: 조화 | E18: 목성-상승궁 조화 | F18: 확장의 별이 첫인상의 자리를 자연스럽게 돕는 각도 — 새 사람과 새 배움이 기분을 가볍게 해요 | G18: 새로 만난 사람이나 짧은 배움이 기분을 한결 가볍게 해 주었을 수 있어요. | H18: 처음 가 보는 곳, 처음 만나는 사람에게 문을 열기 좋은 때예요. | I18: 확장의 별이 첫인상의 자리를 자연스럽게 돕는 각도에 있습니다. 나를 꾸미지 않아도 호감이 전해져, 새로운 만남이 부드럽게 열리기 쉬워요. 퇴근 후 짧은 강의나 처음 인사한 동료와의 대화가 생각보다 오래 힘이 될 수 있습니다. | J18: 순풍 | K18: 열린 문 | M18: 미검수
A19: TR_JUPITER_ASC_TENSE | B19: 목성 | C19: 상승궁 | D19: 긴장 | E19: 목성-상승궁 긴장 | F19: 확장의 별이 첫인상의 자리와 긴장하는 각도 — 넓히려는 마음이 앞서기 쉬워요 | G19: 나를 더 보여 주고 싶어 여러 일을 맡았다가, 조금 벅찼을 수 있어요. | H19: 넓히기보다 지금 가진 것을 지키는 쪽에 무게를 두기 좋은 때입니다. | I19: 확장의 별이 나를 드러내는 자리와 긴장하는 각도를 이룹니다. 더 많이 보여 주고 싶은 마음에 일정과 역할을 늘리기 쉬워요. 새로 벌이는 것은 하나만 고르고 나머지는 지금 가진 것을 지키는 데 두면 균형이 잡힙니다. | J19: 중립 | K19: 균형 | L19: 목성 긴장은 과함·과신 주의로 '중립' 처리 | M19: 미검수
A20: TR_JUPITER_MC_CONJ | B20: 목성 | C20: 천정 | D20: 합 | E20: 목성-천정 합 | F20: 확장의 별이 커리어의 꼭대기에 겹치는 자리 — 일에서 기회와 인정이 열려요 | G20: 일에서 새 기회가 들어오거나, 해 온 일이 눈에 띄는 때였을 거예요. | H20: 일의 목표를 한 단계 높게 그려 보기 좋은 때예요. | I20: 확장의 별이 일과 커리어의 꼭대기 자리에 겹치는 시기예요. 해 온 일이 눈에 띄고, 새로운 역할이나 제안이 들어오기 쉽습니다. 기회가 오면 지금 가는 방향과 이어지는지부터 살펴보고 잡는 편이 좋아요. | J20: 순풍 | K20: 커리어 확장 | M20: 미검수
A21: TR_JUPITER_MC_HARM | B21: 목성 | C21: 천정 | D21: 조화 | E21: 목성-천정 조화 | F21: 확장의 별이 커리어 방향을 자연스럽게 돕는 각도 — 일의 흐름이 순하게 풀려요 | G21: 일이 순하게 풀리고, 도와주는 사람이 곁에 있었을 수 있습니다. | H21: 일에서 도움을 청하고 협업을 넓혀 보기 좋은 때입니다. | I21: 확장의 별이 커리어 방향을 자연스럽게 돕는 각도에 있어요. 무리하지 않아도 일이 조금씩 앞으로 나가고, 동료나 윗사람의 지지를 얻기 쉽습니다. 원하는 방향을 주변에 한 번 말해 두면 연결이 생기기 좋은 때예요. | J21: 순풍 | K21: 일의 순풍 | M21: 미검수
A22: TR_JUPITER_MC_TENSE | B22: 목성 | C22: 천정 | D22: 긴장 | E22: 목성-천정 긴장 | F22: 확장의 별이 커리어 방향과 긴장하는 각도 — 일과 생활의 균형이 기울기 쉬워요 | G22: 일 욕심이 커지거나, 일과 집 사이에서 마음이 바빴을 거예요. | H22: 일의 목표를 현실적인 크기로 다듬기 좋은 때예요. | I22: 확장의 별이 커리어 방향과 긴장하는 각도를 이룹니다. 더 큰 자리나 성과를 바라는 마음이 커지는 만큼, 일과 생활의 균형이 한쪽으로 기울기 쉬워요. 욕심나는 기회가 와도 지금의 일상이 감당할 수 있는지 함께 따져 보면 좋습니다. | J22: 중립 | K22: 현실적 목표 | L22: 목성 긴장은 과함·과신 주의로 '중립' 처리 | M22: 미검수
A23: TR_SATURN_SUN_CONJ | B23: 토성 | C23: 태양 | D23: 합 | E23: 토성-태양 합 | F23: 책임의 별이 나의 중심을 누르는 자리 — 맡은 역할의 무게를 실감하게 해요 | G23: 책임이 한꺼번에 몰려 지치고, ‘나는 잘하고 있나’를 자주 물었을 거예요. | H23: 해야 할 일과 내려놓을 일을 가려내기 좋은 때입니다. | I23: 책임의 별이 나의 중심에 겹치는 시기입니다. 맡은 역할이 무겁게 느껴지고 피로가 쌓이기 쉬워, 평소보다 속도가 나지 않을 수 있어요. 그래도 이 시기에 정리한 우선순위는 이후 몇 해를 버티는 단단한 뼈대가 됩니다. | J23: 역풍 | K23: 책임의 무게 | M23: 미검수
A24: TR_SATURN_SUN_HARM | B24: 토성 | C24: 태양 | D24: 조화 | E24: 토성-태양 조화 | F24: 책임의 별이 나의 중심을 받쳐 주는 각도 — 꾸준함이 인정으로 돌아와요 | G24: 꾸준히 해 온 일이 조금씩 인정받고, 내 자리가 단단해졌을 수 있어요. | H24: 오래갈 계획을 세우고 차근차근 쌓아 가기 좋은 때예요. | I24: 책임의 별이 나의 중심을 자연스럽게 받쳐 주는 각도에 있습니다. 화려하진 않아도 들인 노력이 그대로 결과로 남기 쉬워요. 길게 보고 시작하는 공부나 계획이 있다면 이때 뼈대를 세워 두기 좋습니다. | J24: 순풍 | K24: 쌓이는 인정 | M24: 미검수
A25: TR_SATURN_SUN_TENSE | B25: 토성 | C25: 태양 | D25: 긴장 | E25: 토성-태양 긴장 | F25: 책임의 별이 나의 중심과 긴장하는 각도 — 압박 속에서 내 힘을 시험받아요 | G25: 뜻대로 풀리지 않는 일이 이어져, 스스로를 의심한 때가 있었을 거예요. | H25: 속도보다 방향을 점검하며 버티는 힘을 기르기 좋은 때입니다. | I25: 책임의 별이 나의 중심과 긴장하는 각도를 이룹니다. 노력에 비해 결과가 더디거나, 바깥의 기대와 내 마음이 부딪치는 느낌이 들기 쉬워요. 이 압박을 지나며 정말 지킬 것과 놓아도 될 것이 분명해지고, 그만큼 나에 대한 믿음이 단단해집니다. | J25: 역풍 | K25: 버티는 힘 | M25: 미검수
A26: TR_SATURN_MOON_CONJ | B26: 토성 | C26: 달 | D26: 합 | E26: 토성-달 합 | F26: 책임의 별이 감정의 별과 겹치는 자리 — 마음이 무겁고 혼자 감당하려 하기 쉬워요 | G26: 마음이 무거워 혼자 삭이는 날이 많고, 집과 가까운 사람에 대한 책임이 더해졌을 수 있어요. | H26: 힘든 마음을 혼자 견디기보다 기댈 곳을 구체적으로 마련하기 좋은 때예요. | I26: 책임의 별이 감정의 별과 겹치는 시기입니다. 마음이 쉽게 가라앉고, 힘든 티를 내지 않은 채 혼자 견디려 하기 쉬워요. 이 무게를 지나며 내가 무엇에서 안정을 얻는지 분명해지고, 감정을 돌보는 나만의 방법이 생길 수 있어요. | J26: 역풍 | K26: 마음의 무게 | L26: ‘집과 가까운 사람에 대한 책임’ 표현 수위 확인 부탁 | M26: 미검수
A27: TR_SATURN_MOON_HARM | B27: 토성 | C27: 달 | D27: 조화 | E27: 토성-달 조화 | F27: 책임의 별이 감정의 별을 받쳐 주는 각도 — 마음에 단단한 바닥이 생겨요 | G27: 마음이 차분히 가라앉고, 생활이 조금씩 자리를 잡아 갔을 거예요. | H27: 생활 리듬과 집의 질서를 단단히 다지기 좋은 때입니다. | I27: 책임의 별이 감정의 별을 자연스럽게 받쳐 주는 각도에 있어요. 감정이 크게 출렁이지 않고, 생활의 질서 속에서 안정을 느끼기 쉽습니다. 잠드는 시간이나 집 정리처럼 작은 루틴을 정해 두면 오래가는 안정이 돼요. | J27: 순풍 | K27: 안정 | M27: 미검수
A28: TR_SATURN_MOON_TENSE | B28: 토성 | C28: 달 | D28: 긴장 | E28: 토성-달 긴장 | F28: 책임의 별이 감정의 별과 긴장하는 각도 — 의무와 마음 사이에서 무게를 느껴요 | G28: 해야 할 일과 마음이 원하는 것 사이에서 지치고, 외롭게 느낀 때가 있었을 수 있어요. | H28: 내 감정이 보내는 신호를 적어 보고, 쉬는 시간을 먼저 정하기 좋은 때입니다. | I28: 책임의 별이 감정의 별과 긴장하는 각도를 이룹니다. 바깥의 의무와 마음의 필요가 부딪쳐, 쉬어도 쉰 것 같지 않거나 서운함이 쌓이기 쉬워요. 이 시기에 감정을 미루지 않고 다루는 법을 익혀 두면, 그것이 다음 시기의 든든한 바탕이 됩니다. | J28: 역풍 | K28: 감정 돌보기 | M28: 미검수
A29: TR_SATURN_MERCURY_CONJ | B29: 토성 | C29: 수성 | D29: 합 | E29: 토성-수성 합 | F29: 책임의 별이 생각·말의 별과 겹치는 자리 — 말과 판단이 신중하고 무거워져요 | G29: 생각이 많아져 말을 아끼거나, 서류·계약 같은 일에 신경 쓸 게 많았을 거예요. | H29: 생각을 글로 정리하고 하나씩 결론 내기 좋은 때예요. | I29: 책임의 별이 생각과 말의 별에 겹치는 시기입니다. 머리가 무겁고 말이 쉽게 나오지 않을 수 있지만, 그만큼 판단은 신중해져요. 공부나 문서, 계약처럼 꼼꼼함이 필요한 일을 차근차근 마무리하기에는 오히려 잘 맞는 흐름입니다. | J29: 역풍 | K29: 신중한 생각 | M29: 미검수
A30: TR_SATURN_MERCURY_HARM | B30: 토성 | C30: 수성 | D30: 조화 | E30: 토성-수성 조화 | F30: 책임의 별이 생각·말의 별을 받쳐 주는 각도 — 집중하고 정리하는 힘이 좋아져요 | G30: 집중해서 공부하거나 일을 체계적으로 정리해 낸 성과가 있었을 수 있어요. | H30: 자격·공부·문서처럼 오래 남는 일에 집중하기 좋은 때입니다. | I30: 책임의 별이 생각과 말의 별을 자연스럽게 받쳐 주는 각도에 있습니다. 생각이 차분하게 정리되고, 약속과 말에 무게가 실려 신뢰를 얻기 쉬워요. 미뤄 둔 공부나 긴 계획을 구체적인 순서로 적어 보기 좋은 시기예요. | J30: 순풍 | K30: 집중 | M30: 미검수
A31: TR_SATURN_MERCURY_TENSE | B31: 토성 | C31: 수성 | D31: 긴장 | E31: 토성-수성 긴장 | F31: 책임의 별이 생각·말의 별과 긴장하는 각도 — 걱정이 많아지고 말이 막히기 쉬워요 | G31: 말이 엇갈리거나 일이 서류 단계에서 늦어져 답답했을 거예요. | H31: 중요한 말과 결정은 기록으로 남기며 천천히 가기 좋은 때예요. | I31: 책임의 별이 생각과 말을 맡은 별과 긴장하는 각도를 이룹니다. 걱정이 꼬리를 물고, 하고 싶은 말이 제대로 전해지지 않는 느낌이 들기 쉬워요. 대신 이 시기에 생각을 글로 정리하고 확인하는 습관을 들이면, 말에 오래가는 신뢰가 쌓입니다. | J31: 역풍 | K31: 기록하기 | M31: 미검수
A32: TR_SATURN_VENUS_CONJ | B32: 토성 | C32: 금성 | D32: 합 | E32: 토성-금성 합 | F32: 책임의 별이 좋아하는 것·관계의 별과 겹치는 자리 — 관계와 돈을 진지하게 돌아보게 해요 | G32: 관계나 돈을 현실적으로 따져 보게 되고, 즐거움이 조금 줄었을 수 있어요. | H32: 오래 곁에 둘 관계와 소비를 가려 보기 좋은 때입니다. | I32: 책임의 별이 좋아하는 것과 관계를 맡은 별에 겹치는 시기예요. 즐거움보다 책임이 앞서고, 관계와 씀씀이를 진지하게 따져 보기 쉽습니다. 이 시기를 지나며 내가 정말 아끼는 것이 무엇인지 분명해지고, 오래갈 관계에 마음을 더 쏟을 수 있어요. | J32: 역풍 | K32: 가치 점검 | L32: 관계 변화(이별 등) 예측으로 읽히지 않도록 ‘따져 보기·아끼는 것’ 중심으로 씀 | M32: 미검수
A33: TR_SATURN_VENUS_HARM | B33: 토성 | C33: 금성 | D33: 조화 | E33: 토성-금성 조화 | F33: 책임의 별이 좋아하는 것·관계의 별을 받쳐 주는 각도 — 관계와 살림이 차분히 안정돼요 | G33: 믿을 수 있는 관계가 조금씩 깊어지고, 돈 관리도 차분해졌을 거예요. | H33: 오래가는 관계와 생활 습관에 꾸준히 마음을 쓰기 좋은 때예요. | I33: 책임의 별이 좋아하는 것과 관계를 맡은 별을 자연스럽게 받쳐 주는 각도에 있습니다. 화려한 설렘보다 믿음이 쌓이는 관계, 충동보다 계획이 있는 소비가 편안하게 느껴지기 쉬워요. 오래 함께한 사람에게 꾸준한 마음을 표현해 보기 좋은 시기입니다. | J33: 순풍 | K33: 믿음 | M33: 미검수
A34: TR_SATURN_VENUS_TENSE | B34: 토성 | C34: 금성 | D34: 긴장 | E34: 토성-금성 긴장 | F34: 책임의 별이 좋아하는 것·관계의 별과 긴장하는 각도 — 관계에서 거리감이나 아쉬움을 느끼기 쉬워요 | G34: 관계에서 서운함을 느끼거나, 하고 싶은 것을 참아야 하는 때가 있었을 수 있어요. | H34: 관계와 돈에서 내 기준을 다시 세워 보기 좋은 때입니다. | I34: 책임의 별이 좋아하는 것과 관계를 맡은 별과 긴장하는 각도를 이룹니다. 마음을 줘도 돌아오는 것이 적게 느껴지거나, 즐거움을 미뤄야 하는 상황이 생기기 쉬워요. 이 아쉬움 속에서 나에게 필요한 관계와 소비의 기준이 또렷해지고, 그 기준이 나를 지켜 줍니다. | J34: 역풍 | K34: 나의 기준 | M34: 미검수
A35: TR_SATURN_MARS_CONJ | B35: 토성 | C35: 화성 | D35: 합 | E35: 토성-화성 합 | F35: 책임의 별이 행동의 별과 겹치는 자리 — 브레이크를 밟은 채 달리는 느낌이 들어요 | G35: 마음은 급한데 일이 뜻대로 나가지 않아 답답했을 거예요. | H35: 속도를 늦추고 힘을 한 곳에 모으기 좋은 때입니다. | I35: 책임의 별이 의욕과 행동의 별에 겹치는 시기입니다. 움직이고 싶은데 제동이 걸리는 느낌이라 답답함이나 짜증이 쌓이기 쉬워요. 대신 이때 다진 끈기는 서두르지 않고 끝까지 해내는 힘으로 남아요. | J35: 역풍 | K35: 끈기 | M35: 미검수
A36: TR_SATURN_MARS_HARM | B36: 토성 | C36: 화성 | D36: 조화 | E36: 토성-화성 조화 | F36: 책임의 별이 행동의 별을 받쳐 주는 각도 — 힘을 오래, 효율적으로 쓰게 해요 | G36: 체계적으로 움직이며 오래 걸리던 일을 마무리했을 수 있습니다. | H36: 긴 호흡이 필요한 일을 계획대로 밀고 가기 좋은 때예요. | I36: 책임의 별이 의욕의 별을 자연스럽게 받쳐 주는 각도에 있어요. 힘을 낭비하지 않고, 계획한 만큼 꾸준히 움직이기 쉽습니다. 일이든 운동이든 매일 조금씩 하는 방식이 눈에 띄는 결과로 쌓이기 좋은 때예요. | J36: 순풍 | K36: 꾸준한 실행 | M36: 미검수
A37: TR_SATURN_MARS_TENSE | B37: 토성 | C37: 화성 | D37: 긴장 | E37: 토성-화성 긴장 | F37: 책임의 별이 행동의 별과 긴장하는 각도 — 막히는 일 앞에서 화가 쌓이기 쉬워요 | G37: 벽에 부딪히는 일이 잦아 화가 나거나, 힘이 빠졌던 때가 있었을 거예요. | H37: 화가 날 때 바로 맞서기보다 방법을 바꿔 보기 좋은 때예요. | I37: 책임의 별이 의욕의 별과 긴장하는 각도를 이룹니다. 노력해도 막히는 느낌이 들고, 그 답답함이 화나 무기력으로 번지기 쉬워요. 이 시기에 힘을 쓰는 방법을 바꿔 보면, 무리하지 않고도 앞으로 가는 요령이 생깁니다. | J37: 역풍 | K37: 힘의 방향 | M37: 미검수
A38: TR_SATURN_ASC_CONJ | B38: 토성 | C38: 상승궁 | D38: 합 | E38: 토성-상승궁 합 | F38: 책임의 별이 나를 드러내는 자리에 겹치는 때 — 나 자신을 새로 세우는 무게를 느껴요 | G38: 한결 진지하고 어른스러워지면서 스스로에게 엄격해졌을 수 있어요. | H38: 나를 어떤 사람으로 세울지 차분히 정해 보기 좋은 때입니다. | I38: 책임의 별이 나를 드러내는 자리에 겹치는 시기입니다. 몸과 마음의 리듬이 무겁게 느껴지고, 스스로에게 더 엄격한 기준을 들이대기 쉬워요. 이 시기에 생활 리듬과 나를 보여 주는 방식을 정돈해 두면, 오래가는 새로운 나의 기반이 돼요. | J38: 역풍 | K38: 나를 세우기 | M38: 미검수
A39: TR_SATURN_ASC_HARM | B39: 토성 | C39: 상승궁 | D39: 조화 | E39: 토성-상승궁 조화 | F39: 책임의 별이 첫인상의 자리를 받쳐 주는 각도 — 믿음직한 사람으로 비치게 해요 | G39: 주변에서 믿고 맡기는 일이 늘고, 차분한 사람으로 보였을 거예요. | H39: 생활 루틴을 다지고 신뢰를 쌓아 가기 좋은 때예요. | I39: 책임의 별이 첫인상의 자리를 자연스럽게 받쳐 주는 각도에 있습니다. 말과 행동이 안정돼 보여, 사람들이 믿고 기대기 쉬워요. 잠과 식사 같은 생활 리듬을 정해 두기에도 잘 맞는 시기입니다. | J39: 순풍 | K39: 믿음직함 | M39: 미검수
A40: TR_SATURN_ASC_TENSE | B40: 토성 | C40: 상승궁 | D40: 긴장 | E40: 토성-상승궁 긴장 | F40: 책임의 별이 첫인상의 자리와 긴장하는 각도 — 주변의 기대가 나를 누르는 느낌이 들어요 | G40: 주변의 기대와 요구에 맞추느라 내 모습이 작게 느껴졌을 수 있어요. | H40: 남의 기대와 내 기준을 나눠 보기 좋은 때입니다. | I40: 책임의 별이 나를 드러내는 자리와 긴장하는 각도를 이룹니다. 관계나 일에서 오는 요구가 커져, 나답게 움직일 여지가 줄어든 느낌이 들기 쉬워요. 이 압박을 지나며 어디까지 맞추고 어디서 선을 그을지 알게 되고, 그 선이 나를 단단하게 지켜 줍니다. | J40: 역풍 | K40: 나의 선 | M40: 미검수
...

Sheet A9 목성·토성 하우스 통과
A1: ID | B1: 행성 | C1: 하우스 | D1: 하우스 이름 | E1: 한 해 키워드 | F1: 다른 표현(테마 겹칠 때) | G1: 표 셀 한 문장 | H1: 본문(2~3문장) | I1: 기회/남는 것 | J1: 주의/무게 다루는 법 | K1: 검수 메모 | L1: 검수상태 | M1: 수정 문장 | N1: 상담사 메모
A2: JUP_H01 | B2: 목성 | C2: 1 | D2: 1하우스 · 나 자신 | E2: 나를 넓히는 해 | F2: 내 모습이 넓어지는 해 · 나를 드러내기 좋은 해 | G2: 나를 드러낼 기회가 늘고 자신감이 자라기 좋은 때예요. | H2: 확장의 별이 나 자신의 자리에 머무는 시기입니다. 새 자리에서 먼저 인사하거나 미뤄 둔 계획을 꺼내 보이기가 한결 쉬워져요. 눈에 띄는 일이 늘어나도 어색해하기보다 나답게 받아들여 보세요. | I2: 나를 소개할 자리가 오면 미루지 말고 한 번 나서 보세요. | J2: 들뜬 기분에 약속과 일을 한꺼번에 늘리기 쉬우니 하나씩 받는 편이 좋습니다. | L2: 미검수
A3: JUP_H02 | B3: 목성 | C3: 2 | D3: 2하우스 · 돈·내 것 | E3: 내 가치를 키우는 해 | F3: 내 것이 자라는 해 · 쓸 줄 아는 힘이 커지는 해 | G3: 내가 잘하는 것의 값어치를 다시 알아보기 좋은 때입니다. | H3: 확장의 별이 돈과 내 것의 자리를 지나며 '나는 무엇을 줄 수 있는가'에 대한 답을 넓혀 줍니다. 내 기술이나 시간에 제값을 매기는 연습이 자연스러워지는 시기예요. 작은 부수입이나 내 재주의 새로운 쓰임새를 발견하는 장면으로 나타나기도 해요. | I3: 내가 가진 기술을 필요로 하는 곳이 보이면 가볍게 제안해 보세요. | J3: 여유가 느껴질수록 지출도 커지기 쉬우니 큰 구매는 한 번 더 따져 보는 편이 좋습니다. | K3: 돈 영역이라 '수입이 는다' 같은 단정은 피하고 자기가치·쓰임새 중심으로 썼음. 표현 수위 확인 부탁. | L3: 미검수
A4: JUP_H03 | B4: 목성 | C4: 3 | D4: 3하우스 · 배움·말 | E4: 배우고 말하는 해 | F4: 배움이 넓어지는 해 · 가까운 대화가 힘이 되는 해 | G4: 짧은 배움과 가까운 대화가 힘이 되는 때예요. | H4: 확장의 별이 배움과 말의 자리에 머물러 호기심이 커지는 시기입니다. 짧은 강의, 글쓰기, 가까운 사람과의 대화가 생각보다 큰 문을 열어 줘요. 동네를 오가거나 가까운 곳에 다니며 새 정보를 얻는 일도 늘어나기 쉬워요. | I4: 관심 가는 짧은 수업이나 모임이 보이면 한 번 들어가 보세요. | J4: 이것저것 동시에 시작하기 쉬우니 끝까지 해 볼 한 가지를 먼저 정해 두세요. | L4: 미검수
A5: JUP_H04 | B5: 목성 | C5: 4 | D5: 4하우스 · 집·마음의 뿌리 | E5: 뿌리를 넓히는 해 | F5: 집과 마음이 넓어지는 해 · 돌아올 자리가 커지는 해 | G5: 집과 가족, 마음 둘 곳이 넓어지기 좋은 때입니다. | H5: 확장의 별이 집과 마음의 뿌리 자리에 들어와 쉴 곳을 넓혀 주는 시기예요. 생활 공간을 손보는 일이나 가족과 보내는 시간이 마음을 든든하게 채워 줍니다. 돌아갈 곳이 단단해지면 바깥일을 대하는 마음도 한결 느긋해져요. | I5: 내가 편히 쉬는 공간을 한 곳 정해 정성껏 가꿔 보세요. | J5: 집 관련 큰 결정은 기분보다 현실 조건을 먼저 확인한 뒤 움직이는 편이 좋습니다. | L5: 미검수
A6: JUP_H05 | B6: 목성 | C6: 5 | D6: 5하우스 · 즐거움·창작 | E6: 즐거움이 돌아오는 해 | F6: 좋아하는 일이 커지는 해 · 마음껏 즐겨 보는 해 | G6: 좋아하는 것을 다시 즐기고 만들기 좋은 때예요. | H6: 확장의 별이 즐거움과 창작의 자리를 비추는 시기입니다. 미뤄 둔 취미나 만들고 싶던 것을 시작하기에 마음이 가벼워져요. 설레는 일이 늘어나는 만큼 나를 웃게 하는 것이 무엇인지 알아보기 좋습니다. | I6: 오래 미뤄 둔 취미 하나를 이번에는 직접 시작해 보세요. | J6: 재미에 빠져 쉬는 시간까지 다 쓰지 않도록 즐거움에도 끝나는 시간을 정해 두세요. | K6: 5하우스는 연애의 자리이기도 하지만 만남 권유 금지 규칙에 따라 '설레는 일' 정도로만 썼음. | L6: 미검수
A7: JUP_H06 | B7: 목성 | C7: 6 | D7: 6하우스 · 일상·루틴 | E7: 일상을 가꾸는 해 | F7: 하루가 단단해지는 해 · 몸과 일의 리듬이 좋아지는 해 | G7: 매일의 일과 루틴이 한결 수월해지기 좋은 때입니다. | H7: 확장의 별이 매일의 일과 몸 관리 자리에 머무는 시기예요. 일하는 방식을 손보거나 새 루틴을 들이기에 힘이 실립니다. 작은 습관 하나가 하루의 리듬을 바꾸는 장면을 만날 수 있어요. | I7: 일을 덜어 줄 도구나 방법이 보이면 미루지 말고 바로 써 보세요. | J7: 할 수 있다는 마음에 업무를 너무 많이 받기 쉬우니 거절할 몫도 남겨 두세요. | L7: 미검수
